File: MaterialsAutomated3-RTAnalysis/20110927_AFe2X3.dat
[Header]
TITLE, BaFe2S2.54Se0.46 and Ba0.1K0.9Fe2Se3 and Ba0.7K0.3Fe2Se3
FILEOPENTIME, 23263781.63, 9/27/2011, 9:10 AM
BYAPP, Resistivity, 2.0, 1.0
INFO, APPNAME, PPMS MultiVu Application, Release 1.5.0.19
INFO, BaFe2S2.54Se0.46, Sample1 Name
INFO, 1, Sample1 Cross Section
INFO, 1, Sample1 Length
INFO, Ohm, Sample1 Units
INFO, Ba0.1K0.9Fe2Se3, Sample2 Name
INFO, 1, Sample2 Cross Section
INFO, 1, Sample2 Length
INFO, Ohm, Sample2 Units
INFO, Ba0.7K0.3Fe2Se3, Sample3 Name
INFO, 1, Sample3 Cross Section
INFO, 1, Sample3 Length
INFO, Ohm, Sample3 Units
INFO, , Sample4 Name
INFO, 1, Sample4 Cross Section
INFO, 1, Sample4 Length
INFO, Ohm-m, Sample4 Units
FIELDGROUP, Resistivity,2,3,4,5,6,7,8,9,10,11,12,13,14,15,16,17,18,19,20,21,22,23,24,25,26,27,28,29,30,31,32,33,34,35,36,37,38,39,40,41
STARTUPGROUP, Resistivity
STARTUPAXIS, X, 2, LINEAR, AUTO
STARTUPAXIS, Y1, 7, LINEAR, AUTO
STARTUPAXIS, Y2, 9, LINEAR, AUTO
STARTUPAXIS, Y3, 11, LINEAR, AUTO
PLOT_APPEARANCE, ALL, HORZ_GRID_ON, VERT_GRID_ON, MARKERS_AND_LINES, ALL_LINES
DATATYPE, TIME, 2
DATATYPE, COMMENT, 1
[Data]
Comment,Time Stamp (sec),Status (code),Temperature (K),Magnetic Field (Oe),Sample Position (deg),Bridge 1 Resistivity (Ohm),Bridge 1 Excitation (uA),Bridge 2 Resistivity (Ohm),Bridge 2 Excitation (uA),Bridge 3 Resistivity (Ohm),Bridge 3 Excitation (uA),Bridge 4 Resistivity (Ohm-m),Bridge 4 Excitation (uA),Bridge 1 Std. Dev. (Ohm),Bridge 2 Std. Dev. (Ohm),Bridge 3 Std. Dev. (Ohm),Bridge 4 Std. Dev. (Ohm-m),Number of Readings,Bridge 1 Resistance (Ohms),Bridge 2 Resistance (Ohms),Bridge 3 Resistance (Ohms),Bridge 4 Resistance (Ohms),Signal 1 Vin (V),Signal 2 Vin (V),Digital Inputs (code),Drive 1 Iout (mA),Drive 1 Ipower (watts),Drive 2 Iout (mA),Drive 2 Ipower (watts),Pressure (),Map 20 (),Map 21 (),Map 22 (),Map 23 (),Map 24 (),Map 25 (),Map 26 (),Map 27 (),Map 28 (),Map 29 ()
,23263871.23,4369,300.001586914063,-0.116999998688698,-7.98000001907349,4.97593269348145,500,39.744776763916,500,16.6228229522705,500,,,0.000130049303595299,0.00295084826075579,0.0012944193909698,,25,4.97593269348145,39.744776763916,16.6228229522705,
,23264455.56,4370,296.456604003906,-0.116999998688698,-7.98000001907349,5.20580224990845,500,40.3206918334961,500,16.943860244751,500,,,0.0213168931300598,0.0891058367860462,0.042472488884975,,25,5.20580224990845,40.3206918334961,16.943860244751,
,23264606.66,4370,291.802444458008,-0.116999998688698,-7.98000001907349,5.74148496627808,500,42.5756585693359,500,18.0062561035156,500,,,0.00909687877441628,0.0366713085838774,0.017154851806264,,25,5.74148496627808,42.5756585693359,18.0062561035156,
,23264751.67,4370,286.794204711914,-0.116999998688698,-7.98000001907349,6.31656465530395,500,44.8753674316406,500,19.1056086730957,500,,,0.0121599460412434,0.0475745272274853,0.0230272754591523,,25,6.31656465530395,44.8753674316406,19.1056086730957,
,23264904.33,4370,281.801406860352,-0.116999998688698,-7.98000001907349,6.98569145202637,500,47.4517196655273,500,20.3531537628174,500,,,0.013157682386622,0.0494011264860102,0.0239403870382903,,25,6.98569145202637,47.4517196655273,20.3531537628174,
,23265053.75,4370,276.794189453125,-0.116999998688698,-7.98000001907349,7.71522855758667,500,50.1614855957031,500,21.6913343048096,500,,,0.0151001243699006,0.0552442645212006,0.0275935498360693,,25,7.71522855758667,50.1614855957031,21.6913343048096,
,23265204.38,4370,271.786911010742,-0.116999998688698,-7.98000001907349,8.54761829376221,500,53.1198794555664,500,23.1903177642822,500,,,0.0170369104367093,0.0590657958551647,0.0305104031267983,,25,8.54761829376221,53.1198794555664,23.1903177642822,
,23265353.31,4370,266.811386108398,-0.116999998688698,-7.98000001907349,9.49216136932373,500,56.3471780395508,500,24.8701180267334,500,,,0.019536825755241,0.0653208619740443,0.0335353498262813,,25,9.49216136932373,56.3471780395508,24.8701180267334,
,23265504.38,4370,261.779296875,-0.116999998688698,-7.98000001907349,10.5597482681274,500,59.8825973510742,500,26.7427485656738,500,,,0.021642554627466,0.0703955782336709,0.0373476117648586,,25,10.5597482681274,59.8825973510742,26.7427485656738,
,23265654.00,4370,256.801651000977,-0.116999998688698,-7.98000001907349,11.7423524856567,500,63.6820373535156,500,28.8111552429199,500,,,0.0238886449423321,0.0767063592747512,0.0432120924583971,,25,11.7423524856567,63.6820373535156,28.8111552429199,
,23265803.86,4370,251.807350158691,-0.116999998688698,-7.98000001907349,13.0626941680908,500,67.8428903198242,500,31.1640773773193,500,,,0.026900375230934,0.0834333052525962,0.0456298620126089,,25,13.0626941680908,67.8428903198242,31.1640773773193,
,23265954.39,4370,246.788101196289,-0.116999998688698,-7.98000001907349,14.5249071121216,500,72.398408203125,500,33.7488136291504,500,,,0.029557032124935,0.0909449779127033,0.051238315025415,,25,14.5249071121216,72.398408203125,33.7488136291504,
,23266103.77,4370,241.813697814941,-0.116999998688698,-7.98000001907349,16.1377532958984,500,77.3566473388672,500,36.5976142883301,500,,,0.0327479596445318,0.100468923759339,0.0575093645014374,,25,16.1377532958984,77.3566473388672,36.5976142883301,
,23266254.16,4370,236.783897399902,-0.116999998688698,-7.98000001907349,17.9355834960937,500,82.8744427490234,500,39.8198678588867,500,,,0.0366356199869928,0.112375693393473,0.0675072077055938,,25,17.9355834960937,82.8744427490234,39.8198678588867,
,23266403.67,4370,231.816551208496,-0.116999998688698,-7.98000001907349,19.8749424743652,500,88.9011901855469,500,43.4066809082031,500,,,0.0390141737696664,0.120553211227573,0.0702118170637899,,25,19.8749424743652,88.9011901855469,43.4066809082031,
,23266553.53,4370,226.809097290039,-0.116999998688698,-7.98000001907349,21.9880291748047,500,95.5242767333984,500,47.3874694824219,500,,,0.0420761383786126,0.131672000610066,0.0824789582124312,,25,21.9880291748047,95.5242767333984,47.3874694824219,
,23266703.39,4370,221.803649902344,-0.116999998688698,-7.98000001907349,24.2642765045166,500,102.837364501953,500,51.9078776550293,500,,,0.0470817005563369,0.151422860071228,0.098401894142487,,25,24.2642765045166,102.837364501953,51.9078776550293,
,23266853.25,4370,216.817001342773,-0.116999998688698,-7.98000001907349,26.6913446044922,500,111.098723144531,500,56.9546781921387,500,,,0.0482272436183657,0.165679464497209,0.104919810150792,,25,26.6913446044922,111.098723144531,56.9546781921387,
,23267003.95,4370,211.774749755859,-0.116999998688698,-7.98000001907349,29.2741136169434,500,120.198517150879,500,62.840983581543,500,,,0.0522622925252244,0.190108601348716,0.122620478545785,,25,29.2741136169434,120.198517150879,62.840983581543,
,23267153.17,4370,206.811546325684,-0.116999998688698,-7.98000001907349,31.9551710510254,500,130.196357421875,500,69.5454840087891,500,,,0.0534672912327708,0.204560282627225,0.142390194580614,,25,31.9551710510254,130.196357421875,69.5454840087891,
,23267303.45,4370,201.801902770996,-0.116999998688698,-7.98000001907349,34.7499673461914,500,141.381208496094,500,77.2381851196289,500,,,0.0576293940188154,0.24139449818655,0.170102024976598,,25,34.7499673461914,141.381208496094,77.2381851196289,
,23267453.70,4370,196.797050476074,-0.116999998688698,-7.98000001907349,37.6882698059082,500,153.940440063477,500,86.1727865600586,500,,,0.0572210447341025,0.256231116437756,0.185393739309993,,25,37.6882698059082,153.940440063477,86.1727865600586,
,23267603.05,4370,191.821800231934,-0.116999998688698,-7.98000001907349,40.7379783630371,500,167.965111083984,500,96.6632345581055,500,,,0.0604711579558622,0.28632773504773,0.206054594875315,,25,40.7379783630371,167.965111083984,96.6632345581055,
,23267753.17,4370,186.801147460938,-0.116999998688698,-7.98000001907349,43.9785736083984,500,183.998776245117,500,109.043288879395,500,,,0.0550451226226916,0.369705793097336,0.25278045257688,,25,43.9785736083984,183.998776245117,109.043288879395,
,23267903.63,4370,181.751998901367,-0.116999998688698,-7.98000001907349,47.4713777160645,500,202.44016418457,469.33080078125,123.362762145996,500,,,0.088098940335453,0.478625491185701,0.359556508913666,,25,47.4713777160645,202.44016418457,123.362762145996,
,23268052.63,4370,176.789398193359,-0.116999998688698,-7.98000001907349,51.2668629455566,500,222.930776367187,426.184720458984,140.266690063477,500,,,0.092586742923206,0.544242035772982,0.421877470226729,,25,51.2668629455566,222.930776367187,140.266690063477,
,23268203.45,4370,171.754745483398,-0.116999998688698,-7.98000001907349,55.5797500610352,500,246.833123168945,384.895,160.301495361328,500,,,0.103265950851834,0.576256484444286,0.490611675557388,,25,55.5797500610352,246.833123168945,160.301495361328,
,23268353.14,4370,166.673652648926,-0.116999998688698,-7.98000001907349,60.5836627197266,500,274.494180908203,346.028359375,201.08137878418,472.721037597656,,,0.186473503699075,1.00347904134903,1.02811455346409,,25,60.5836627197266,274.494180908203,201.08137878418,
,23268503.02,4370,161.676795959473,-0.116999998688698,-7.98000001907349,66.3064340209961,500,306.085501708984,310.288240966797,232.862131958008,408.158364257812,,,0.219013048437491,1.17219860187931,1.17478069202222,,25,66.3064340209961,306.085501708984,232.862131958008,
,23268653.06,4370,156.689300537109,-0.116999998688698,-7.98000001907349,73.2256066894531,500,342.728760986328,277.049398193359,269.583695068359,352.554958496094,,,0.250760801750304,1.32517491576646,1.31952409768329,,25,73.2256066894531,342.728760986328,269.583695068359,
,23268803.72,4370,151.68775177002,-0.116999998688698,-7.98000001907349,81.6664706420898,500,386.410308837891,245.735159912109,315.536076660156,301.182202148438,,,0.293797311433313,1.41767835533401,1.53123507345404,,25,81.6664706420898,386.410308837891,315.536076660156,
,23268953.80,4370,146.703598022461,-0.116999998688698,-7.98000001907349,92.0313897705078,500,436.636890869141,217.450001220703,372.127083740234,255.359078979492,,,0.318212452972885,1.52407050539855,1.70720625715349,,25,92.0313897705078,436.636890869141,372.127083740234,
,23269103.28,4370,141.737655639648,-0.116999998688698,-7.98000001907349,105.055856628418,500,496.230577392578,191.372721557617,439.092614746094,216.375199584961,,,0.366264750515408,1.62289176385794,1.97451522094738,,25,105.055856628418,496.230577392578,439.092614746094,
,23269252.77,4370,136.760604858398,-0.116999998688698,-7.98000001907349,121.749509277344,500,567.122573242188,167.386480712891,523.96822265625,181.289760742188,,,0.45461559646656,1.87541011046475,2.27469136042839,,25,121.749509277344,567.122573242188,523.96822265625,
,23269403.27,4370,131.769348144531,-0.116999998688698,-7.98000001907349,143.370260009766,500,653.022824707031,145.402958374023,634.08759765625,149.721519775391,,,0.510626341809524,1.92549572500295,2.50036960214064,,25,143.370260009766,653.022824707031,634.08759765625,
,23269552.73,4370,126.781200408936,-0.116999998688698,-7.98000001907349,172.013649902344,500,756.646027832031,125.471440429688,772.97638671875,122.804079284668,,,0.70049881416099,2.43019624566473,3.36596096281729,,25,172.013649902344,756.646027832031,772.97638671875,
,23269703.44,4370,121.540748596191,-0.116999998688698,-7.98000001907349,212.974880371094,446.624362792969,889.443095703125,106.712319641113,961.170070800781,98.7396798706055,,,2.21479758242815,6.79337940975074,9.67447966441624,,25,212.974880371094,889.443095703125,961.170070800781,
,23269853.03,4370,116.627098083496,-0.116999998688698,-7.98000001907349,265.503603515625,358.212042236328,1043.41834960937,90.962360534668,1188.78416015625,79.7753601074219,,,2.52981215563522,6.67108073360329,10.0668971215437,,25,265.503603515625,1043.41834960937,1188.78416015625,
,23270003.22,4370,111.612602233887,-0.116999998688698,-7.98000001907349,341.680483398438,278.387880859375,1239.15184082031,76.56087890625,1498.41411132813,63.2731596374512,,,3.73194263744152,8.61051952135619,13.8302863537783,,25,341.680483398438,1239.15184082031,1498.41411132813,
,23270153.00,4370,106.588901519775,-0.116999998688698,-7.98000001907349,452.620333251953,210.034238891602,1483.76775878906,63.8886793518066,1907.34625,49.781240234375,,,5.36864235621404,11.383422250271,20.6985612425991,,25,452.620333251953,1483.76775878906,1907.34625,
,23270302.53,4370,101.549648284912,-0.116999998688698,-7.98000001907349,616.168291015625,154.079119873047,1798.69016601563,52.7015199279785,2458.0596484375,38.7112799072266,,,9.85986376072011,17.8815342802461,32.2320300768236,,25,616.168291015625,1798.69016601563,2458.0596484375,
,23270512.33,4370,94.5155487060547,-0.116999998688698,-7.98000001907349,988.380266113281,96.0429998779297,2393.81377929688,39.7469200134277,3539.00415039063,26.8773599243164,,,19.7020686178056,28.4839208216719,53.2093895719716,,25,988.380266113281,2393.81377929688,3539.00415039063,
,23270692.59,4370,88.5575523376465,-0.116999998688698,-7.98000001907349,1543.73825683594,61.4264801025391,3086.05825195312,30.8186798095703,4850.73498046875,19.5915998840332,,,30.0661350065537,35.1489830735472,60.3771892970635,,25,1543.73825683594,3086.05825195312,4850.73498046875,
,23270842.14,4370,83.5272483825684,-0.116999998688698,-7.98000001907349,2360.58310546875,40.3938003540039,3869.497734375,24.538399887085,6356.6056640625,14.9331199264526,,,59.1856320876963,49.3133433935065,96.8678000101417,,25,2360.58310546875,3869.497734375,6356.6056640625,
,23270992.58,4370,78.5144996643066,-0.116999998688698,-7.98000001907349,3760.53180664062,25.3629600524902,4895.474765625,19.395240020752,8308.38357421875,11.4284799575806,,,105.925769068601,64.7696659497284,124.892321080298,,25,3760.53180664062,4895.474765625,8308.38357421875,
,23271142.66,4370,73.6255531311035,-0.116999998688698,-7.98000001907349,6226.8024609375,15.2955199050903,6219.116640625,15.2683199310303,10738.6938671875,8.83339988708496,,,147.15634559506,65.3498658995768,127.047434953725,,25,6226.8024609375,6219.116640625,10738.6938671875,
,23271293.08,4370,68.6327514648438,-0.116999998688698,-7.98000001907349,11212.3164453125,8.49439994812012,8018.92990234375,11.832919960022,13939.5470703125,6.80124000549316,,,278.476899522601,81.6983880021996,139.917290711611,,25,11212.3164453125,8018.92990234375,13939.5470703125,
,23271443.13,4370,63.5420513153076,-0.116999998688698,-7.98000001907349,22100.410625,4.32139999389648,10412.410625,9.10599987030029,18098.15953125,5.23592000961304,,,792.011844264828,134.296438017118,226.641189485207,,25,22100.410625,10412.410625,18098.15953125,
,23271592.67,4370,58.5446510314941,-0.116999998688698,-7.98000001907349,47002.884375,2.02647998809814,13474.0956640625,7.03664001464844,23462.816953125,4.05419998168945,,,1988.3611751719,175.118313503538,317.20260916799,,25,47002.884375,13474.0956640625,23462.816953125,
,23271743.36,4370,53.5193996429443,-0.116999998688698,-7.98000001907349,110666.0146875,0.861119999885559,17336.150390625,5.46359992980957,30376.46265625,3.12504000663757,,,5662.10438334473,234.86581451268,447.467473366541,,25,110666.0146875,17336.150390625,30376.46265625,
,23271923.91,4370,47.4803504943848,-0.116999998688698,-7.98000001907349,364555.56875,0.255639998912811,23250.09390625,4.08971997261047,42216.30109375,2.24952000617981,,,21680.5358262066,319.80918075333,674.847083686178,,25,364555.56875,23250.09390625,42216.30109375,
,23272073.59,4370,42.5641994476318,-0.116999998688698,-7.98000001907349,1119703.175,0.0796799993515015,29723.08390625,3.19691999435425,60473.1578125,1.56771999835968,,,64360.4171680233,367.192482846154,1067.01170340803,,25,1119703.175,29723.08390625,60473.1578125,
,23272222.70,4370,37.6185989379883,-0.116999998688698,-7.98000001907349,3614011.73,0.0203199998289347,38097.94375,2.49223998069763,89359.0940625,1.05932000160217,,,151935.68443801,425.092973901194,1637.58643785275,,25,3614011.73,38097.94375,89359.0940625,
,23272373.34,4370,32.6258506774902,-0.116999998688698,-7.98000001907349,2158950.055,0.00700000021606684,50677.1790625,1.87252000331879,146529.503125,0.643799998760223,,,376909.115189031,638.947499790355,3282.10171533596,,25,2158950.055,50677.1790625,146529.503125,
,23272522.94,4370,27.681450843811,-0.116999998688698,-7.98000001907349,,0.0020000000949949,71165.35125,1.33184000015259,276135.53,0.339320005178452,,,,920.644250136299,6680.48853593552,,25,,71165.35125,276135.53,
,23272673.23,4370,22.7192506790161,-0.116999998688698,-7.98000001907349,,0.0020000000949949,109974.6015625,0.859879996776581,654440.8875,0.140159999132156,,,,1539.53725141856,18426.7126148437,,25,,109974.6015625,654440.8875,
,23272824.13,4370,17.7256002426147,-0.116999998688698,-7.98000001907349,-609168.5225,0.0470800003409386,201966.739375,0.463999998569489,2352159.49,0.0350000011920929,,,127282.348218166,3948.57831942833,97477.6474676434,,25,-609168.5225,201966.739375,2352159.49,
,23272973.98,4370,12.543399810791,-0.116999998688698,-7.98000001907349,-130961.790500959,31.1108408300392,563567.195,0.162719998955727,,0.00408000014722347,,,141494.776409668,27562.6207912846,,,21,-130961.790500959,563567.195,,
,23273373.23,4375,8.00804996490479,-0.116999998688698,-7.98000001907349,,0.0020000000949949,2738079.69,0.0255600004643202,,0.0020000000949949,,,,88820.4439692052,,,25,,2738079.69,,
,23273891.61,4374,2.88999998569489,-0.116999998688698,-7.98000001907349,,0.0020000000949949,,0.0020000000949949,,0.0020000000949949,,,,,,,25,,,,
,23275599.63,4370,7.09130001068115,49999.91015625,-7.98000001907349,,0.0020000000949949,,0.0020000000949949,,0.0020000000949949,,,,,,,25,,,,
,23275752.56,4370,12.1935000419617,49999.91015625,-7.98000001907349,,0.0020000000949949,623080.615,0.137119998931885,,0.0020000000949949,,,,16002.6007959124,,,25,,623080.615,,
,23275904.59,4370,17.2606496810913,49999.91015625,-7.98000001907349,-229350.533125,0.171359999924898,225722.790625,0.393160004615784,2966676.86,0.0244800002872944,,,51260.6833235742,4513.58173345884,127281.364541679,,25,-229350.533125,225722.790625,2966676.86,
,23276055.81,4370,22.2004508972168,49999.91015625,-7.98000001907349,,0.0020000000949949,119790.7375,0.75,778642.41,0.109200001955032,,,,1239.82602046566,16631.8068179884,,25,,119790.7375,778642.41,
,23276206.61,4370,27.2127504348755,49999.91015625,-7.98000001907349,,0.0020000000949949,75640.5296875,1.17471995830536,309908.75875,0.28600001335144,,,,574.527801520752,4574.48543519163,,25,,75640.5296875,309908.75875,
,23276357.41,4370,32.2191009521484,49999.91015625,-7.98000001907349,,0.0020000000949949,53218.70609375,1.68915999889374,159458.3425,0.5603600025177,,,,335.236795719379,1842.14804972022,,25,,53218.70609375,159458.3425,
,23276508.48,4370,37.2310009002686,49999.91015625,-7.98000001907349,4180943.27,0.0149999996647239,39840.73484375,2.24759999275208,95677.5434375,0.930999994277954,,,69601.4932708293,207.47440892078,837.603156057285,,25,4180943.27,39840.73484375,95677.5434375,
,23276658.16,4370,42.2017002105713,49999.91015625,-7.98000001907349,1336548.18,0.0612800012528896,30922.24265625,2.96000003814697,63641.98125,1.410640001297,,,32210.2662615757,152.995810656288,487.085012421054,,25,1336548.18,30922.24265625,63641.98125,
,23276809.30,4370,47.2207984924316,49999.91015625,-7.98000001907349,429494.445,0.204999996423721,24254.9821875,3.75927989959717,44742.11609375,2.03215996742249,,,9199.90816147286,117.214369813301,303.418321791125,,25,429494.445,24254.9821875,44742.11609375,
,23276959.42,4370,52.2101993560791,49999.91015625,-7.98000001907349,157705.693125,0.562520003318787,19225.5359375,4.64995981216431,34302.21921875,2.60400009155273,,,2925.29506996552,90.6843391396039,171.74709877329,,25,157705.693125,19225.5359375,34302.21921875,
,23277109.23,4370,57.2064990997314,49999.91015625,-7.98000001907349,65381.74671875,1.37015997886658,15080.788671875,5.98515993118286,26518.80046875,3.38483993530273,,,1095.0946802924,75.0063760769101,142.404853535616,,25,65381.74671875,15080.788671875,26518.80046875,
,23277259.52,4370,62.1982517242432,49999.91015625,-7.98000001907349,30062.410546875,2.99243992805481,11776.002734375,7.7189998626709,20656.316953125,4.38984008789063,,,441.735441407312,58.6308007102919,100.077453087212,,25,30062.410546875,11776.002734375,20656.316953125,
,23277410.17,4370,67.202751159668,49999.91015625,-7.98000001907349,15146.7012109375,5.95307989120483,9164.2600390625,9.79500007629395,16165.086015625,5.66699981689453,,,193.111219380498,45.193871477278,80.1776007325255,,25,15146.7012109375,9164.2600390625,16165.086015625,
,23277560.45,4370,72.1958503723145,49999.91015625,-7.98000001907349,8250.9978515625,10.8820795440674,7145.10900390625,12.4820003509521,12632.6375,7.18100023269653,,,91.5656306820318,34.1951851866385,58.9176807329503,,25,8250.9978515625,7145.10900390625,12632.6375,
,23277710.75,4370,77.2035484313965,49999.91015625,-7.98000001907349,4813.4859765625,18.7024403381348,5601.58349609375,15.8769998550415,9801.9700390625,9.08600044250488,,,47.9863569001119,26.3594163052445,49.8587310679799,,25,4813.4859765625,5601.58349609375,9801.9700390625,
,23277860.58,4370,82.1880531311035,49999.91015625,-7.98000001907349,2969.18391601563,30.2066008758545,4421.1997265625,20.2000007629395,7578.414140625,12.0460396575928,,,26.6802574212387,20.0930650166599,38.7564605930016,,25,2969.18391601563,4421.1997265625,7578.414140625,
,23278010.66,4370,87.1903495788574,49999.91015625,-7.98000001907349,1918.99589355469,46.7461990356445,3517.23658203125,25.7450008392334,5828.0519140625,15.3879995346069,,,15.5537980460819,15.4271018554421,29.1132779101563,,25,1918.99589355469,3517.23658203125,5828.0519140625,
,23278161.11,4370,92.2084007263184,49999.91015625,-7.98000001907349,1284.04772949219,70.3470001220703,2814.7063671875,32.102838973999,4469.3889453125,20.3325196075439,,,9.75011511111309,12.1981555132298,23.9163501944296,,25,1284.04772949219,2814.7063671875,4469.3889453125,
,23278310.47,4370,97.1799011230469,49999.91015625,-7.98000001907349,894.010344238281,101.123602294922,2282.3165625,39.7900009155273,3445.2958203125,26.2089996337891,,,6.08255355193772,9.18268667391741,17.5347715358125,,25,894.010344238281,2282.3165625,3445.2958203125,
,23278461.58,4370,102.22465133667,49999.91015625,-7.98000001907349,641.881086425781,139.404361572266,1868.56028320313,48.314998626709,2665.57436523437,33.4389991760254,,,3.95236342042226,7.05343528841662,13.3464843523298,,25,641.881086425781,1868.56028320313,2665.57436523437,
,23278610.36,4370,107.187000274658,49999.91015625,-7.98000001907349,474.149151611328,192.964996337891,1548.86325195313,58.1339988708496,2083.50951171875,42.6230010986328,,,2.70152211557297,5.50925463863895,9.58737269776542,,25,474.149151611328,1548.86325195313,2083.50951171875,
,23278760.92,4370,112.204452514648,49999.91015625,-7.98000001907349,357.223946533203,253.541314697266,1293.53074707031,70.1029968261719,1641.9128125,54.226001739502,,,1.88828441974405,4.44163877080667,7.16408316789701,,25,357.223946533203,1293.53074707031,1641.9128125,
,23278910.73,4370,117.199249267578,49999.91015625,-7.98000001907349,277.475207519531,328.529998779297,1090.5009375,82.1005599975586,1309.97349121094,68.6370010375977,,,1.28635830738661,3.57686075100485,5.87077560858831,,25,277.475207519531,1090.5009375,1309.97349121094,
,23279060.84,4370,122.20779800415,49999.91015625,-7.98000001907349,221.234915161133,405.998608398438,926.52875,97.947998046875,1052.61026855469,87.0348764038086,,,0.941148744082672,2.898356978991,4.56979136707882,,25,221.234915161133,926.52875,1052.61026855469,
,23279210.92,4370,127.191051483154,49999.91015625,-7.98000001907349,180.326123657227,500,793.466240234375,113.092002868652,854.985991210938,105.276000976563,,,0.671758245617136,2.30765312811464,3.212322137782,,25,180.326123657227,793.466240234375,854.985991210938,
,23279360.83,4370,132.199745178223,49999.91015625,-7.98000001907349,149.917911376953,500,684.290834960937,130.679000854492,701.782690429687,127.259002685547,,,0.504202757718773,1.90611270612329,2.57835212811307,,25,149.917911376953,684.290834960937,701.782690429687,
,23279510.52,4370,137.196998596191,49999.91015625,-7.98000001907349,127.025756225586,500,594.072075195313,150.953002929688,581.344890136719,154.128005981445,,,0.384039162953533,1.57773111036877,2.08504259306389,,25,127.025756225586,594.072075195313,581.344890136719,
,23279660.11,4370,142.177352905273,49999.91015625,-7.98000001907349,109.396045837402,500,519.396555175781,174.401992797852,485.838055419922,186.858993530273,,,0.302455669628851,1.33315282378304,1.62362489793786,,25,109.396045837402,519.396555175781,485.838055419922,
,23279810.47,4370,147.190650939941,49999.91015625,-7.98000001907349,95.6011029052734,500,456.334055175781,201.514007568359,409.354565429688,216.599878540039,,,0.236246298733395,1.11099561995489,1.3674757715388,,25,95.6011029052734,456.334055175781,409.354565429688,
,23279961.00,4370,152.210151672363,49999.91015625,-7.98000001907349,84.5593267822266,500,402.97265625,222.031997680664,347.062861328125,262.334991455078,,,0.195217049185899,0.956940416269549,1.08713385505099,,25,84.5593267822266,402.97265625,347.062861328125,
,23280110.86,4370,157.20890045166,49999.91015625,-7.98000001907349,75.7180850219727,500,358.051531982422,256.472991943359,296.809237060547,303.371002197266,,,0.153857167109031,0.800612432178312,0.887932718126949,,25,75.7180850219727,358.051531982422,296.809237060547,
,23280260.11,4370,162.199501037598,49999.91015625,-7.98000001907349,68.4407778930664,500,319.661591796875,282.609008789063,256.008548583984,350.756988525391,,,0.132625821900592,0.696260700571526,0.69379106542458,,25,68.4407778930664,319.661591796875,256.008548583984,
,23280410.84,4370,167.214302062988,49999.91015625,-7.98000001907349,62.3337814331055,500,286.4286328125,311.18701171875,221.48296875,405.471008300781,,,0.10735934990578,0.58689233832481,0.633124019285697,,25,62.3337814331055,286.4286328125,221.48296875,
,23280560.86,4370,172.221298217773,49999.91015625,-7.98000001907349,57.192861328125,500,257.843068847656,342.696990966797,192.745180664063,468.97900390625,,,0.0938322671918301,0.521410011522253,0.517072341948527,,25,57.192861328125,257.843068847656,192.745180664063,
,23280710.81,4370,177.221649169922,49999.91015625,-7.98000001907349,52.7350003051758,500,233.016646118164,390.171437988281,168.696611328125,500,,,0.0813905422661123,0.462223229461239,0.439851930550424,,25,52.7350003051758,233.016646118164,168.696611328125,
,23280860.45,4370,182.20539855957,49999.91015625,-7.98000001907349,48.7995178222656,500,211.407053222656,429.926564941406,148.325183105469,500,,,0.0727505271550885,0.405486945419772,0.361017263571056,,25,48.7995178222656,211.407053222656,148.325183105469,
,23281010.59,4370,187.221000671387,49999.91015625,-7.98000001907349,45.2176338195801,500,192.368091430664,465.501115722656,130.970686035156,500,,,0.0679133577178834,0.348936132984007,0.311777824319462,,25,45.2176338195801,192.368091430664,130.970686035156,
,23281160.72,4370,192.219947814941,49999.91015625,-7.98000001907349,41.9088819885254,500,175.527601318359,500,115.986357727051,500,,,0.0615829933308739,0.300775365096507,0.267561484518337,,25,41.9088819885254,175.527601318359,115.986357727051,
,23281310.02,4370,197.194847106934,49999.91015625,-7.98000001907349,38.814037322998,500,160.727076416016,500,103.191502075195,500,,,0.0584892658435171,0.269176142516531,0.234106098741444,,25,38.814037322998,160.727076416016,103.191502075195,
,23281460.36,4370,202.205902099609,49999.91015625,-7.98000001907349,35.8453564453125,500,147.535615844727,500,92.1706045532227,500,,,0.0556940566325738,0.237774469661611,0.193644313937639,,25,35.8453564453125,147.535615844727,92.1706045532227,
,23281609.75,4370,207.192443847656,49999.91015625,-7.98000001907349,33.0252911376953,500,135.861342163086,500,82.6549954223633,500,,,0.0535203327960262,0.215632265643295,0.16945411632034,,25,33.0252911376953,135.861342163086,82.6549954223633,
,23281760.31,4370,212.21565246582,49999.91015625,-7.98000001907349,30.298620223999,500,125.361454162598,500,74.1647552490234,500,,,0.0508383651142513,0.191233624559391,0.157127553211445,,25,30.298620223999,125.361454162598,74.1647552490234,
,23281910.00,4370,217.204696655273,49999.91015625,-7.98000001907349,27.7171444702148,500,116.037157897949,500,66.8493502807617,500,,,0.0483966130259827,0.170317639543136,0.135215830192156,,25,27.7171444702148,116.037157897949,66.8493502807617,
,23282060.61,4370,222.22534942627,49999.91015625,-7.98000001907349,25.2545733642578,500,107.627176818848,500,60.504782409668,500,,,0.0452817385155309,0.152774938766297,0.114611567839804,,25,25.2545733642578,107.627176818848,60.504782409668,
,23282210.02,4370,227.19930267334,49999.91015625,-7.98000001907349,22.927306137085,500,100.137544250488,500,54.9304106140137,500,,,0.0437048897373714,0.140742725975393,0.0987476563022701,,25,22.927306137085,100.137544250488,54.9304106140137,
,23282358.94,4370,232.190505981445,49999.91015625,-7.98000001907349,20.7325135803223,500,93.2235354614258,500,50.2754022216797,500,,,0.040739601944848,0.126482521102576,0.0839237729272722,,25,20.7325135803223,93.2235354614258,50.2754022216797,
,23282509.36,4370,237.189407348633,49999.91015625,-7.98000001907349,18.7225879669189,500,87.0098654174805,500,46.2611811828613,500,,,0.0373771181997517,0.11265449119356,0.0769190256763226,,25,18.7225879669189,87.0098654174805,46.2611811828613,
,23282659.67,4370,242.193298339844,49999.91015625,-7.98000001907349,16.8557270050049,500,81.1136920166016,500,42.5416062927246,500,,,0.0340958382849334,0.108515073248915,0.0684420414117844,,25,16.8557270050049,81.1136920166016,42.5416062927246,
,23282810.14,4370,247.222602844238,49999.91015625,-7.98000001907349,15.1494464874268,500,75.7838067626953,500,39.2456904602051,500,,,0.0311120357326987,0.0976177730746654,0.0593207812768395,,25,15.1494464874268,75.7838067626953,39.2456904602051,
,23282959.44,4370,252.196846008301,49999.91015625,-7.98000001907349,13.6240812301636,500,71.0039541625977,500,36.3319006347656,500,,,0.0280141115106522,0.0870847089445885,0.0550022151928468,,25,13.6240812301636,71.0039541625977,36.3319006347656,
,23283109.80,4370,257.21174621582,49999.91015625,-7.98000001907349,12.2404773712158,500,66.5868911743164,500,33.677308807373,500,,,0.0250687391348641,0.0811628100236786,0.0495370551413596,,25,12.2404773712158,66.5868911743164,33.677308807373,
,23283258.83,4370,262.173309326172,49999.91015625,-7.98000001907349,11.0103511810303,500,62.5857000732422,500,31.2849105834961,500,,,0.0224003408477437,0.0740770347015669,0.0417985133996843,,25,11.0103511810303,62.5857000732422,31.2849105834961,
,23283409.55,4370,267.190460205078,49999.91015625,-7.98000001907349,9.89450302124023,500,58.8694369506836,500,29.0893523406982,500,,,0.0198978528761744,0.0677627758302615,0.0397619799996046,,25,9.89450302124023,58.8694369506836,29.0893523406982,
,23283560.53,4370,272.22380065918,49999.91015625,-7.98000001907349,8.90151023864746,500,55.4274758911133,500,27.0997822570801,500,,,0.0178274063965694,0.0625476039920806,0.0374060787702047,,25,8.90151023864746,55.4274758911133,27.0997822570801,
,23283709.28,4370,277.186859130859,49999.91015625,-7.98000001907349,8.02862854003906,500,52.3049545288086,500,25.3289756774902,500,,,0.0158413286420832,0.0599943531516267,0.0333284819430176,,25,8.02862854003906,52.3049545288086,25.3289756774902,
,23283860.00,4370,282.204208374023,49999.91015625,-7.98000001907349,7.25720895767212,500,49.3794496154785,500,23.7033099365234,500,,,0.0141495615558942,0.0543357116979154,0.030065661680617,,25,7.25720895767212,49.3794496154785,23.7033099365234,
,23284010.14,4370,287.206893920898,49999.91015625,-7.98000001907349,6.56678821563721,500,46.6675805664063,500,22.2303221130371,500,,,0.0126527001560765,0.0511501451565534,0.0273601557409736,,25,6.56678821563721,46.6675805664063,22.2303221130371,
,23284159.98,4370,292.205612182617,49999.91015625,-7.98000001907349,5.95324783325195,500,44.1392031860352,500,20.8854218292236,500,,,0.0113364474787721,0.0471345141707126,0.0247983749151685,,25,5.95324783325195,44.1392031860352,20.8854218292236,
,23284309.75,4370,297.200698852539,49999.91015625,-7.98000001907349,5.4085160446167,500,41.7766976928711,500,19.6550598907471,500,,,0.0102322815616797,0.0465398602398989,0.0245890343892086,,25,5.4085160446167,41.7766976928711,19.6550598907471,
,23284459.69,4370,302.197052001953,49999.91015625,-7.98000001907349,4.92776924133301,500,39.5643858337402,500,18.504513092041,500,,,0.00877862647705286,0.0421664714968261,0.0221670248405777,,25,4.92776924133301,39.5643858337402,18.504513092041,
,23284610.05,4370,307.205642700195,49999.91015625,-7.98000001907349,4.48071964263916,500,37.4435780334473,500,17.4402484893799,500,,,0.00907425477765315,0.039424730321547,0.0197366508686833,,25,4.48071964263916,37.4435780334473,17.4402484893799,
,23284760.59,4370,312.207992553711,49999.91015625,-7.98000001907349,4.09193206787109,500,35.4214309692383,500,16.4456436157227,500,,,0.00770444939979129,0.038261414837029,0.0187397547956456,,25,4.09193206787109,35.4214309692383,16.4456436157227,
,23284910.44,4370,317.20654296875,49999.91015625,-7.98000001907349,3.77903287887573,500,33.4821229553223,500,15.5262907028198,500,,,0.00490455007867752,0.037527590754896,0.0176054765569775,,25,3.77903287887573,33.4821229553223,15.5262907028198,
,23285060.27,4370,322.197708129883,49999.91015625,-7.98000001907349,3.49017467498779,500,31.5960752105713,500,14.6427515029907,500,,,0.00511134633280519,0.0362869446691804,0.0166083210615657,,25,3.49017467498779,31.5960752105713,14.6427515029907,
,23285210.50,4370,327.205200195313,49999.91015625,-7.98000001907349,3.22979516983032,500,29.7617400360107,500,13.8115730285645,500,,,0.00496698463836935,0.0346172692397946,0.0151079783694692,,25,3.22979516983032,29.7617400360107,13.8115730285645,
,23285360.05,4370,332.194458007813,49999.91015625,-7.98000001907349,2.98802619934082,500,27.9907827758789,500,13.0356815338135,500,,,0.00444120193344193,0.0344464373405647,0.0143801789086405,,25,2.98802619934082,27.9907827758789,13.0356815338135,
,23285511.19,4370,337.218292236328,49999.91015625,-7.98000001907349,2.78585790634155,500,26.2820320892334,500,12.3020662307739,500,,,0.00434878929249253,0.0321976522862527,0.0140284564532946,,25,2.78585790634155,26.2820320892334,12.3020662307739,
,23285660.69,4370,342.195861816406,49999.91015625,-7.98000001907349,2.58786358833313,500,24.6849203491211,500,11.6168714523315,500,,,0.00372245516419792,0.0293314921150623,0.0123553870692307,,25,2.58786358833313,24.6849203491211,11.6168714523315,
,23285810.97,4370,347.212142944336,49999.91015625,-7.98000001907349,2.40303645133972,500,23.2084304046631,500,10.9797252655029,500,,,0.00359582129932737,0.0278429511463088,0.0121366240889124,,25,2.40303645133972,23.2084304046631,10.9797252655029,
,23285961.11,4370,352.200805664063,49999.91015625,-7.98000001907349,2.23411973953247,500,21.8436374664307,500,10.3823541641235,500,,,0.00315025626617774,0.0252995819298596,0.0114533917083859,,25,2.23411973953247,21.8436374664307,10.3823541641235,
,23286111.17,4370,357.212554931641,49999.91015625,-7.98000001907349,2.08139916419983,500,20.5891914367676,500,9.82729568481445,500,,,0.00276285274796856,0.0233207192337567,0.0105187158819917,,25,2.08139916419983,20.5891914367676,9.82729568481445,
,23286261.19,4370,362.209548950195,49999.91015625,-7.98000001907349,1.93900119304657,500,19.465269317627,500,9.30974178314209,500,,,0.00228018724774038,0.0207421580345135,0.00950813102895522,,25,1.93900119304657,19.465269317627,9.30974178314209,
,23286411.31,4370,367.228393554688,49999.91015625,-7.98000001907349,1.77002778053284,500,18.4328674316406,500,8.82448844909668,500,,,0.0612326775953103,0.0183992571261704,0.00883520629525582,,25,1.77002778053284,18.4328674316406,8.82448844909668,
,23286561.03,4370,372.201904296875,49999.91015625,-7.98000001907349,1.70146653652191,500,17.5094330596924,500,8.36474552154541,500,,,0.00217422136779054,0.0177458952117733,0.00893324974817994,,25,1.70146653652191,17.5094330596924,8.36474552154541,
,23286711.84,4370,377.222351074219,49999.91015625,-7.98000001907349,1.59742970466614,500,16.6550678253174,500,7.91472015380859,500,,,0.00188850401442685,0.0153823154769654,0.00798475118493735,,25,1.59742970466614,16.6550678253174,7.91472015380859,
,23286860.73,4370,382.175247192383,49999.91015625,-7.98000001907349,1.50363399505615,500,15.8707092285156,500,7.51040828704834,500,,,0.00166912472536301,0.0138583850027156,0.00719316241361059,,25,1.50363399505615,15.8707092285156,7.51040828704834,
,23287011.48,4370,387.210494995117,49999.91015625,-7.98000001907349,1.41675368785858,500,15.1519115447998,500,7.11785066604614,500,,,0.00158033226761897,0.0129381029300571,0.00698199233775015,,25,1.41675368785858,15.1519115447998,7.11785066604614,
,23287161.83,4370,392.218658447266,49999.91015625,-7.98000001907349,1.33700048923492,500,14.5032930374146,500,6.75772710800171,500,,,0.00146610245669426,0.0124281853378647,0.00679235781034728,,25,1.33700048923492,14.5032930374146,6.75772710800171,
,23287311.05,4370,397.192108154297,49999.91015625,-7.98000001907349,1.26466012954712,500,13.9258544921875,500,6.4221773147583,500,,,0.00129693786483648,0.0105314224345799,0.0061316197897126,,25,1.26466012954712,13.9258544921875,6.4221773147583,
,23288603.81,4370,398.858047485352,0.108000002801418,-7.98000001907349,1.21447614192963,500,13.3377660751343,500,6.03632400512695,500,,,0.000762371217981477,0.00479841766567515,0.0023234712766349,,25,1.21447614192963,13.3377660751343,6.03632400512695,
,23288785.33,4374,392.57258605957,0.108000002801418,-7.98000001907349,1.29186514377594,500,13.8109069824219,500,6.28224550247192,500,,,0.00171333185085176,0.0101457599540891,0.00523454840155816,,25,1.29186514377594,13.8109069824219,6.28224550247192,
,23288923.20,4370,387.796096801758,0.108000002801418,-7.98000001907349,1.35539477348328,500,14.1950744628906,500,6.48283527374268,500,,,0.00145132419052575,0.00884008123539091,0.00447740458856099,,25,1.35539477348328,14.1950744628906,6.48283527374268,
,23289070.22,4370,382.78044128418,0.108000002801418,-7.98000001907349,1.43376327037811,500,14.6589921951294,500,6.72770391464233,500,,,0.0015570992474201,0.00901972873891175,0.00475205186676049,,25,1.43376327037811,14.6589921951294,6.72770391464233,
,23289223.91,4370,377.784698486328,0.108000002801418,-7.98000001907349,1.51664852142334,500,15.1359439849854,500,6.98313957214355,500,,,0.00163478043027573,0.0093881308970208,0.00513157033590766,,25,1.51664852142334,15.1359439849854,6.98313957214355,
,23289372.39,4370,372.795639038086,0.108000002801418,-7.98000001907349,1.60464772224426,500,15.6282590866089,500,7.25257730484009,500,,,0.00180965619094419,0.0100792065417796,0.00561341878320082,,25,1.60464772224426,15.6282590866089,7.25257730484009,
,23289521.73,4370,367.817138671875,0.108000002801418,-7.98000001907349,1.70244615077972,500,16.1556015014648,500,7.54725765228272,500,,,0.00201372430877683,0.0106953893872772,0.00590884761574895,,25,1.70244615077972,16.1556015014648,7.54725765228272,
,23289673.28,4370,362.768707275391,0.108000002801418,-7.98000001907349,1.81121531009674,500,16.72292137146,500,7.86299695968628,500,,,0.00216982870172108,0.0110565760961347,0.00614978068891162,,25,1.81121531009674,16.72292137146,7.86299695968628,
,23289821.28,4370,357.811950683594,0.108000002801418,-7.98000001907349,1.92971118450165,500,17.3189647674561,500,8.19923706054687,500,,,0.00243487874983946,0.0121317085473911,0.00697564282899417,,25,1.92971118450165,17.3189647674561,8.19923706054687,
,23289972.11,4370,352.792602539063,0.108000002801418,-7.98000001907349,2.06138161659241,500,17.9586631774902,500,8.55985660552978,500,,,0.0026500892031503,0.0124843192196577,0.0073016448240818,,25,2.06138161659241,17.9586631774902,8.55985660552978,
,23290122.64,4370,347.787155151367,0.108000002801418,-7.98000001907349,1.02870083332062,500,18.6397167205811,500,8.94931144714355,500,,,0.0441098664327274,0.0129938107564907,0.0074879199381247,,25,1.02870083332062,18.6397167205811,8.94931144714355,
,23290272.88,4370,342.796997070313,0.108000002801418,-7.98000001907349,0.922573626041412,500,19.3505055999756,500,9.356032371521,500,,,0.00139092367601083,0.0139945594810141,0.00804393662580396,,25,0.922573626041412,19.3505055999756,9.356032371521,
,23290422.89,4370,337.78825378418,0.108000002801418,-7.98000001907349,1.41453379154205,500,20.1112860107422,500,9.79971008300781,500,,,0.0347928440942261,0.0151615447687457,0.00867596262711156,,25,1.41453379154205,20.1112860107422,9.79971008300781,
,23290572.48,4370,332.797790527344,0.108000002801418,-7.98000001907349,2.73197118759155,500,20.9318046569824,500,10.2810121536255,500,,,0.00396088070309362,0.0163367251686996,0.0097189471972268,,25,2.73197118759155,20.9318046569824,10.2810121536255,
,23290721.80,4370,327.815002441406,0.108000002801418,-7.98000001907349,2.94468390464783,500,21.796072845459,500,10.7897747039795,500,,,0.00429253294499257,0.01721509778985,0.0105480962170004,,25,2.94468390464783,21.796072845459,10.7897747039795,
,23290872.59,4370,322.811050415039,0.108000002801418,-7.98000001907349,3.18330344200134,500,22.7361071777344,500,11.3461500167847,500,,,0.00495214190194184,0.0187021406403434,0.0109834221073609,,25,3.18330344200134,22.7361071777344,11.3461500167847,
,23291023.06,4370,317.78190612793,0.108000002801418,-7.98000001907349,3.449079246521,500,23.7565921020508,500,11.9488510131836,500,,,0.00545181903255271,0.0206260971017895,0.012169914464521,,25,3.449079246521,23.7565921020508,11.9488510131836,
,23291172.58,4370,312.807495117188,0.108000002801418,-7.98000001907349,3.74441053390503,500,24.8716803741455,500,12.6012254714966,500,,,0.00606072074478396,0.0234154139891259,0.0128747635672445,,25,3.74441053390503,24.8716803741455,12.6012254714966,
,23291323.45,4370,307.777786254883,0.108000002801418,-7.98000001907349,4.07455444335938,500,26.1553311157227,500,13.3138074874878,500,,,0.00667398223062172,0.0257574627629316,0.0141183311499087,,25,4.07455444335938,26.1553311157227,13.3138074874878,
,23291472.48,4370,302.809844970703,0.108000002801418,-7.98000001907349,4.4376477432251,500,27.699462890625,500,14.0789627075195,500,,,0.00755593765776645,0.0321258541795703,0.0156397521886249,,25,4.4376477432251,27.699462890625,14.0789627075195,
,23292309.52,5138,298.740905761719,0.108000002801418,-7.98000001907349,4.79354818344116,500,30.2635942840576,500,14.9897692108154,500,,,0.0419027153926772,0.76605920721627,0.200259856971019,,25,4.79354818344116,30.2635942840576,14.9897692108154,
,23292460.27,4370,293.798095703125,0.108000002801418,-7.98000001907349,5.25739831924438,500,31.3049530029297,500,15.8514350891113,500,,,0.00783091520503803,0.0232749654200925,0.0147737668116217,,25,5.25739831924438,31.3049530029297,15.8514350891113,
,23292607.97,4370,288.80110168457,0.108000002801418,-7.98000001907349,5.73244382858276,500,32.7275428771973,500,16.7403972625732,500,,,0.0100862758873862,0.0307579719441462,0.0191228101254689,,25,5.73244382858276,32.7275428771973,16.7403972625732,
,23292757.94,4370,283.782958984375,0.108000002801418,-7.98000001907349,6.28798952102661,500,34.3914764404297,500,17.7740242004395,500,,,0.0114113722934834,0.0341250310638695,0.0215710728108461,,25,6.28798952102661,34.3914764404297,17.7740242004395,
,23292907.17,4370,278.800643920898,0.108000002801418,-7.98000001907349,6.91621635437012,500,36.2837094116211,500,18.937926864624,500,,,0.01287094009018,0.0402077680118058,0.0234908421534199,,25,6.91621635437012,36.2837094116211,18.937926864624,
,23293058.16,4370,273.775955200195,0.108000002801418,-7.98000001907349,7.62572561264038,500,38.4046914672852,500,20.2362226104736,500,,,0.014240255476562,0.0415637437656032,0.0255608704516833,,25,7.62572561264038,38.4046914672852,20.2362226104736,
,23293207.36,4370,268.800445556641,0.108000002801418,-7.98000001907349,8.405149269104,500,40.6265455627441,500,21.6358768463135,500,,,0.0159554650544325,0.0478597171403591,0.0287408016861468,,25,8.405149269104,40.6265455627441,21.6358768463135,
,23293357.47,4370,263.804901123047,0.108000002801418,-7.98000001907349,9.27855430603027,500,42.9295669555664,500,23.197893371582,500,,,0.0179242281324142,0.0351817759263278,0.0321068937183238,,25,9.27855430603027,42.9295669555664,23.197893371582,
,23293507.92,4370,258.792495727539,0.108000002801418,-7.98000001907349,10.2470844650269,500,42.3393246459961,500,24.9222645568848,500,,,0.0196232377057179,0.149986332932663,0.0348861026736816,,25,10.2470844650269,42.3393246459961,24.9222645568848,
,23293657.98,4370,253.795501708984,0.108000002801418,-7.98000001907349,11.3191556930542,500,49.6819660949707,500,26.8461985778809,500,,,0.02158900340875,2.28988091640615,0.0388324004566228,,25,11.3191556930542,49.6819660949707,26.8461985778809,
,23293808.44,4370,248.789199829102,0.108000002801418,-7.98000001907349,12.4920839309692,500,355.130915527344,257.694000244141,28.9735342407227,500,,,0.0239644841585593,2.81845630158928,0.0440414635308522,,25,12.4920839309692,355.130915527344,28.9735342407227,
,23293958.70,4370,243.777801513672,0.108000002801418,-7.98000001907349,13.7719144439697,500,358.357856445313,250.610992431641,31.3315812683105,500,,,0.0254864195495173,6.73154637684801,0.0468919183140921,,25,13.7719144439697,358.357856445313,31.3315812683105,
,23294107.50,4370,238.810356140137,0.108000002801418,-7.98000001907349,15.146700668335,500,371.810599365234,250.610992431641,33.9240623474121,500,,,0.0275216296831219,1.3115074601624,0.0519173533381029,,25,15.146700668335,371.810599365234,33.9240623474121,
,23294257.83,4370,233.775352478027,0.108000002801418,-7.98000001907349,16.6403072357178,500,386.314370117187,243.898157958984,36.8788732910156,500,,,0.0351967945679353,6.28776669823533,0.0700753577231981,,25,16.6403072357178,386.314370117187,36.8788732910156,
,23294408.63,4370,228.765045166016,0.108000002801418,-7.98000001907349,18.2219337463379,500,424.075157470703,223.195198974609,40.173408203125,500,,,0.0322001751617312,1.84516096698906,0.0676412646433353,,25,18.2219337463379,424.075157470703,40.173408203125,
,23294557.81,4370,223.792655944824,0.108000002801418,-7.98000001907349,19.8807355499268,500,430.830704345703,218.250757446289,43.7603115844727,500,,,0.0334241116777486,2.66786894772622,0.0722054694887022,,25,19.8807355499268,430.830704345703,43.7603115844727,
,23294707.50,4370,218.81079864502,0.108000002801418,-7.98000001907349,21.6352822875977,500,457.959422607422,205.423004150391,47.757391204834,500,,,0.0351562957722111,1.40630661231444,0.081434607144832,,25,21.6352822875977,457.959422607422,47.757391204834,
,23294857.94,4370,213.789596557617,0.108000002801418,-7.98000001907349,23.499338760376,500,467.513854980469,199.072006225586,52.2929667663574,500,,,0.0362693542732081,1.79541817637178,0.09484378888849,,25,23.499338760376,467.513854980469,52.2929667663574,
,23295007.39,4370,208.795104980469,0.108000002801418,-7.98000001907349,25.4529719543457,500,499.759444580078,187.19095703125,57.4849136352539,500,,,0.0395448959284934,4.60732900780719,0.111323695241476,,25,25.4529719543457,499.759444580078,57.4849136352539,
,23295157.70,4370,203.795097351074,0.108000002801418,-7.98000001907349,27.4864277648926,500,527.084812011719,177.772039794922,63.4413133239746,500,,,0.0406847984063475,5.81806017469966,0.125994732791088,,25,27.4864277648926,527.084812011719,63.4413133239746,
,23295307.53,4370,198.796501159668,0.108000002801418,-7.98000001907349,29.6049295806885,500,557.532116699219,168.275478515625,70.2458642578125,500,,,0.0416040829191035,2.50294164197017,0.139376877594617,,25,29.6049295806885,557.532116699219,70.2458642578125,
,23295457.89,4370,193.779457092285,0.108000002801418,-7.98000001907349,31.8413736724854,500,594.035158691406,158.554274291992,78.1562670898438,500,,,0.0448519555125925,1.18530367606663,0.169185568462718,,25,31.8413736724854,594.035158691406,78.1562670898438,
,23295607.94,4370,188.76774597168,0.108000002801418,-7.98000001907349,34.2078486633301,500,626.752595214844,150.903802490234,87.399567565918,500,,,0.0494812778783321,1.26239504804201,0.202961531212073,,25,34.2078486633301,626.752595214844,87.399567565918,
,23295757.88,4370,183.768096923828,0.108000002801418,-7.98000001907349,36.7647175598145,500,682.790158691406,138.427122192383,98.172467956543,500,,,0.0565449821731594,1.94266549036292,0.256338989502995,,25,36.7647175598145,682.790158691406,98.172467956543,
,23295907.63,4370,178.790748596191,0.108000002801418,-7.98000001907349,39.5090269470215,500,725.515004882812,130.190994262695,110.88517578125,500,,,0.0569241413959388,1.07548911221409,0.261939777748136,,25,39.5090269470215,725.515004882812,110.88517578125,
,23296057.03,4370,173.796699523926,0.108000002801418,-7.98000001907349,42.6133798217773,500,974.770617675781,96.7953189086914,125.689660949707,500,,,0.0660011100937682,1.60338150327733,0.318168952022233,,25,42.6133798217773,974.770617675781,125.689660949707,
,23296206.73,4370,168.819450378418,0.108000002801418,-7.98000001907349,46.2197758483887,500,1141.30934082031,79.3840026855469,143.697255859375,500,,,0.0754028704821222,3.38361730390793,0.378519294487154,,25,46.2197758483887,1141.30934082031,143.697255859375,
,23296357.19,4370,163.787895202637,0.108000002801418,-7.98000001907349,50.4735873413086,500,1248.99532714844,75.6131994628906,166.198746337891,500,,,0.0957417281116811,3.80125493865743,0.485441837965148,,25,50.4735873413086,1248.99532714844,166.198746337891,
,23296507.39,4370,158.686096191406,0.108000002801418,-7.98000001907349,55.6600296020508,500,1368.70836914063,68.9692782592773,199.313835449219,476.873516845703,,,0.175378994661098,2.7513700324193,0.964087283045052,,25,55.6600296020508,1368.70836914063,199.313835449219,
,23296656.95,4370,153.69620513916,0.108000002801418,-7.98000001907349,61.9192381286621,500,1539.72673828125,61.1625987243652,231.930848388672,409.799644775391,,,0.219435188457258,5.95227596801156,1.14397041221517,,25,61.9192381286621,1539.72673828125,231.930848388672,
,23296776.70,4370,149.902046203613,0.108000002801418,-7.98000001907349,67.8807257080078,500,1652.85187988281,57.0203594970703,262.647485351563,361.866043701172,,,0.199997998833253,4.42748037599571,1.04084100857798,,25,67.8807257080078,1652.85187988281,262.647485351563,