File: MaterialsAutomated3-RTAnalysis/20110928_AFe2X3.dat
[Header]
TITLE, BaFe2S1.24Se1.76 and Ba0.9K0.1Fe2Se3 and Ba0.436K0.564Fe2Se3
FILEOPENTIME, 23307357.33, 9/27/2011, 9:16 PM
BYAPP, Resistivity, 2.0, 1.0
INFO, APPNAME, PPMS MultiVu Application, Release 1.5.0.19
INFO, BaFe2S1.24Se1.76, Sample1 Name
INFO, 1, Sample1 Cross Section
INFO, 1, Sample1 Length
INFO, Ohm, Sample1 Units
INFO, Ba0.9K0.1Fe2Se3, Sample2 Name
INFO, 1, Sample2 Cross Section
INFO, 1, Sample2 Length
INFO, Ohm, Sample2 Units
INFO, Ba0.436K0.564Fe2Se3, Sample3 Name
INFO, 1, Sample3 Cross Section
INFO, 1, Sample3 Length
INFO, Ohm, Sample3 Units
INFO, , Sample4 Name
INFO, 1, Sample4 Cross Section
INFO, 1, Sample4 Length
INFO, Ohm-m, Sample4 Units
FIELDGROUP, Resistivity,2,3,4,5,6,7,8,9,10,11,12,13,14,15,16,17,18,19,20,21,22,23,24,25,26,27,28,29,30,31,32,33,34,35,36,37,38,39,40,41
STARTUPGROUP, Resistivity
STARTUPAXIS, X, 2, LINEAR, AUTO
STARTUPAXIS, Y1, 7, LINEAR, AUTO
STARTUPAXIS, Y2, 9, LINEAR, AUTO
STARTUPAXIS, Y3, 11, LINEAR, AUTO
PLOT_APPEARANCE, ALL, HORZ_GRID_ON, VERT_GRID_ON, MARKERS_AND_LINES, ALL_LINES
DATATYPE, TIME, 2
DATATYPE, COMMENT, 1
[Data]
Comment,Time Stamp (sec),Status (code),Temperature (K),Magnetic Field (Oe),Sample Position (deg),Bridge 1 Resistivity (Ohm),Bridge 1 Excitation (uA),Bridge 2 Resistivity (Ohm),Bridge 2 Excitation (uA),Bridge 3 Resistivity (Ohm),Bridge 3 Excitation (uA),Bridge 4 Resistivity (Ohm-m),Bridge 4 Excitation (uA),Bridge 1 Std. Dev. (Ohm),Bridge 2 Std. Dev. (Ohm),Bridge 3 Std. Dev. (Ohm),Bridge 4 Std. Dev. (Ohm-m),Number of Readings,Bridge 1 Resistance (Ohms),Bridge 2 Resistance (Ohms),Bridge 3 Resistance (Ohms),Bridge 4 Resistance (Ohms),Signal 1 Vin (V),Signal 2 Vin (V),Digital Inputs (code),Drive 1 Iout (mA),Drive 1 Ipower (watts),Drive 2 Iout (mA),Drive 2 Ipower (watts),Pressure (),Map 20 (),Map 21 (),Map 22 (),Map 23 (),Map 24 (),Map 25 (),Map 26 (),Map 27 (),Map 28 (),Map 29 ()
,23307714.91,4370,299.990295410156,0.108000002801418,-7.98000001907349,71.6597595214844,500,20.6743602752686,500,5.41689769744873,500,,,0.00254718965359483,0.000807202921368199,0.00106353273686284,,25,71.6597595214844,20.6743602752686,5.41689769744873,
,23307940.17,4370,292.699203491211,0.108000002801418,-7.98000001907349,89.1457611083984,500,23.9887756347656,500,5.74475736618042,500,,,0.284882889823135,0.0515673122076677,0.00525985974238392,,25,89.1457611083984,23.9887756347656,5.74475736618042,
,23308114.33,4370,286.769439697266,0.108000002801418,-7.98000001907349,106.798571166992,500,27.1395849609375,500,6.04076431274414,500,,,0.329453173984304,0.0577658898264516,0.0193274881802102,,25,106.798571166992,27.1395849609375,6.04076431274414,
,23308292.89,4370,280.809906005859,0.108000002801418,-7.98000001907349,130.450386352539,500,31.1020309448242,500,6.42354694366455,500,,,0.424787952579722,0.0700006441118878,0.00530359998766461,,25,130.450386352539,31.1020309448242,6.42354694366455,
,23308473.44,4370,274.79460144043,0.108000002801418,-7.98000001907349,160.580015258789,500,35.8350102233887,500,6.78258794784546,500,,,0.542595279215132,0.0836639850883171,0.00609387311998491,,25,160.580015258789,35.8350102233887,6.78258794784546,
,23308653.55,4370,268.680099487305,0.108000002801418,-7.98000001907349,198.51104675293,478.837362060547,41.5554772949219,500,7.21436899185181,500,,,1.23455278293371,0.172540456583259,0.0127751804541879,,25,198.51104675293,41.5554772949219,7.21436899185181,
,23308833.33,4370,262.679595947266,0.108000002801418,-7.98000001907349,245.902805786133,386.526639404297,48.2878634643555,500,7.70948667526245,500,,,1.57394768020851,0.208162725669871,0.0133842336704099,,25,245.902805786133,48.2878634643555,7.70948667526245,
,23309013.81,4370,256.718551635742,0.108000002801418,-7.98000001907349,305.528188476562,311.060083007813,56.3654708862305,500,8.25262805938721,500,,,1.72086265386811,0.21867268320939,0.0120920972674688,,25,305.528188476562,56.3654708862305,8.25262805938721,
,23309194.33,4370,250.698844909668,0.108000002801418,-7.98000001907349,382.587757568359,248.431799316406,66.2668878173828,500,8.83537178039551,500,,,2.05598904414133,0.251683238090092,0.0136241446666005,,25,382.587757568359,66.2668878173828,8.83537178039551,
,23309373.94,4370,244.761848449707,0.108000002801418,-7.98000001907349,484.888615722656,195.906119384766,78.3612661743164,500,9.53034725189209,500,,,2.4345285046769,0.248951227845896,0.0144445843125773,,25,484.888615722656,78.3612661743164,9.53034725189209,
,23309552.86,4370,238.801605224609,0.108000002801418,-7.98000001907349,631.69962890625,150.356638793945,93.474446105957,500,10.3592370986938,500,,,3.27692198662751,0.313157490408222,0.0250069823375583,,25,631.69962890625,93.474446105957,10.3592370986938,
,23309733.17,4370,232.789199829102,0.108000002801418,-7.98000001907349,824.417275390625,115.144120483398,112.596548156738,500,11.2695331954956,500,,,3.48450673578579,0.365318841584062,0.0157666049862667,,25,824.417275390625,112.596548156738,11.2695331954956,
,23309913.03,4370,226.799102783203,0.108000002801418,-7.98000001907349,1044.67711425781,90.864599609375,135.111558837891,500,12.219953918457,500,,,4.25819809254751,0.431290874183455,0.0171120326882978,,25,1044.67711425781,135.111558837891,12.219953918457,
,23310093.67,4370,220.778953552246,0.108000002801418,-7.98000001907349,1330.6662109375,71.3043194580078,163.048336791992,500,13.2871488571167,500,,,5.40790654025649,0.532312976676164,0.0185457814638505,,25,1330.6662109375,163.048336791992,13.2871488571167,
,23310273.44,4370,214.685348510742,0.108000002801418,-7.98000001907349,1706.08559082031,55.5936001586914,198.738496704102,478.270758056641,14.5048700332642,500,,,11.4653071758653,1.09872590157725,0.0337208200166581,,25,1706.08559082031,198.738496704102,14.5048700332642,
,23310453.44,4370,208.548347473145,0.108000002801418,-7.98000001907349,2211.1330859375,42.9956399536133,244.956630859375,388.158239746094,15.9107086181641,500,,,24.2211349100216,2.11213784047946,0.0624190648570364,,25,2211.1330859375,244.956630859375,15.9107086181641,
,23310632.61,4370,202.624549865723,0.108000002801418,-7.98000001907349,2860.4216796875,33.246559753418,301.711541748047,314.831481933594,17.4813358306885,500,,,28.1374644807635,2.37509579924771,0.0613305358822101,,25,2860.4216796875,301.711541748047,17.4813358306885,
,23310813.50,4370,196.633949279785,0.108000002801418,-7.98000001907349,3740.82430664062,25.4185601043701,376.410718994141,252.359520874023,19.3306691741943,500,,,31.7988326846067,2.62290362099969,0.0624111227222433,,25,3740.82430664062,376.410718994141,19.3306691741943,
,23310992.92,4370,190.695198059082,0.108000002801418,-7.98000001907349,4923.75078125,19.3043598937988,473.039018554688,200.752279663086,21.4760651397705,500,,,36.9277490756645,2.94942993934938,0.0655947571899524,,25,4923.75078125,473.039018554688,21.4760651397705,
,23311173.75,4370,184.720252990723,0.108000002801418,-7.98000001907349,6531.68390625,14.5295599365234,601.431684570313,157.909119873047,24.0106056213379,500,,,39.8340488258433,3.15043222522917,0.0568476522757622,,25,6531.68390625,601.431684570313,24.0106056213379,
,23311353.78,4370,178.730850219727,0.108000002801418,-7.98000001907349,8770.2473046875,10.8284399795532,774.464040527344,122.549999389648,27.0008945465088,500,,,52.0091295672929,4.01837871387544,0.0646864212254894,,25,8770.2473046875,774.464040527344,27.0008945465088,
,23311532.75,4370,172.777297973633,0.108000002801418,-7.98000001907349,11864.1992578125,7.99804002761841,1009.26166503906,94.0303598022461,30.5639769744873,500,,,69.0830039124396,5.23560110067648,0.0747377868546296,,25,11864.1992578125,1009.26166503906,30.5639769744873,
,23311713.13,4370,166.766647338867,0.108000002801418,-7.98000001907349,16219.3807421875,5.84852001190186,1335.66223144531,71.0209606933594,34.9075277709961,500,,,94.5421830861681,6.95784203330195,0.0876336412480451,,25,16219.3807421875,1335.66223144531,34.9075277709961,
,23311892.80,4370,160.576904296875,0.108000002801418,-7.98000001907349,22646.926484375,4.20087997436523,1817.03640625,52.1543998718262,40.3495500183105,500,,,294.267396152858,21.7179964434388,0.227706705912001,,25,22646.926484375,1817.03640625,40.3495500183105,
,23312073.33,4370,154.530151367188,0.108000002801418,-7.98000001907349,31682.431875,2.99704000473022,2497.90357421875,38.0947201538086,46.9621641540527,500,,,458.210495269765,34.8387625177571,0.300139976155837,,25,31682.431875,2497.90357421875,46.9621641540527,
,23312252.27,4370,148.631103515625,0.108000002801418,-7.98000001907349,44746.96703125,2.12304000854492,3489.49453125,27.2457598876953,55.2052339172363,500,,,527.958822396027,42.4283812716392,0.314086570933106,,25,44746.96703125,3489.49453125,55.2052339172363,
,23312432.48,4370,142.638900756836,0.108000002801418,-7.98000001907349,64308.9503125,1.47427999973297,4966.35318359375,19.1442001342773,65.4660632324219,500,,,772.385747485034,59.4164765538439,0.381650876853532,,25,64308.9503125,4966.35318359375,65.4660632324219,
,23312612.59,4370,136.705101013184,0.108000002801418,-7.98000001907349,93672.654375,1.01096000909805,7197.20240234375,13.2007599258423,78.4549304199219,500,,,924.789283023268,71.3052953464517,0.37803669079998,,25,93672.654375,7197.20240234375,78.4549304199219,
,23312793.13,4370,130.731948852539,0.108000002801418,-7.98000001907349,139726.6175,0.676880006790161,10708.230703125,8.860719871521,95.3224951171875,500,,,1166.1055608015,89.4496571637413,0.39300691701155,,25,139726.6175,10708.230703125,95.3224951171875,
,23312972.88,4370,124.75325012207,0.108000002801418,-7.98000001907349,213279.870625,0.44231999874115,16389.812109375,5.78119995117187,117.647944641113,500,,,1736.20034903163,135.582370242288,0.481208046540115,,25,213279.870625,16389.812109375,117.647944641113,
,23313152.58,4370,118.575950622559,0.108000002801418,-7.98000001907349,338543.445,0.276959993839264,26236.036171875,3.6217599773407,148.683673095703,500,,,6038.07263498252,483.999709800538,1.32764583433143,,25,338543.445,26236.036171875,148.683673095703,
,23313332.70,4370,112.54955291748,0.108000002801418,-7.98000001907349,548610.83,0.169559998512268,42910.45484375,2.21135999679565,190.814541625977,495.945238037109,,,11247.2028315188,925.06623943262,2.07266904887647,,25,548610.83,42910.45484375,190.814541625977,
,23313512.55,4370,106.622501373291,0.108000002801418,-7.98000001907349,915954.3525,0.10027999997139,72018.091875,1.31111999988556,249.811012573242,380.175960693359,,,16208.6177816344,1241.32022578797,2.38923410920757,,25,915954.3525,72018.091875,249.811012573242,
,23313691.70,4370,100.664798736572,0.108000002801418,-7.98000001907349,1597642.75,0.0558000014722347,126372.4609375,0.742720000743866,336.126479492188,282.618519287109,,,31714.5947624094,2513.51534697198,3.54769084867774,,25,1597642.75,126372.4609375,336.126479492188,
,23313872.09,4370,94.6870498657227,0.108000002801418,-7.98000001907349,2916898.2,0.0289199992269278,232879.066875,0.39864000082016,466.609940185547,203.585759277344,,,53403.2828070369,4317.98176297254,4.8372425629553,,25,2916898.2,232879.066875,466.609940185547,
,23314052.20,4370,88.7249488830566,0.108000002801418,-7.98000001907349,5202608.08,0.014039999730885,441625.63875,0.206359997987747,667.055478515625,142.364440917969,,,65256.9627292931,6989.31664984142,6.0869900203235,,25,5202608.08,441625.63875,667.055478515625,
,23314232.38,4370,82.773250579834,0.108000002801418,-7.98000001907349,6308954.08,0.00700000021606684,867919.0225,0.101120000779629,994.602299804688,95.4372402954102,,,105037.130433644,11114.5692202689,7.82042698173182,,25,6308954.08,867919.0225,994.602299804688,
,23314412.83,4370,76.7807006835938,0.108000002801418,-7.98000001907349,-243452.73722168,0.00499999988824129,1750259.04,0.046000000089407,1565.67811523437,60.605719909668,,,174060.780802126,21312.3523418524,13.1384517593788,,25,-243452.73722168,1750259.04,1565.67811523437,
,23314592.73,4370,70.5766525268555,0.108000002801418,-7.98000001907349,,0.0020000000949949,3356589.46,0.019159999601543,2670.44465820313,35.685359954834,,,,59333.7590436013,57.7088101736096,,25,,3356589.46,2670.44465820313,
,23314772.03,4370,64.6299018859863,0.108000002801418,-7.98000001907349,,0.0020000000949949,3606735.91,0.00684000018984079,4824.5015234375,19.7557600402832,,,,250290.361956903,115.277889018084,,25,,3606735.91,4824.5015234375,
,23314951.89,4370,58.6480503082275,0.108000002801418,-7.98000001907349,,0.0020000000949949,,0.0020000000949949,9449.0319921875,10.082080039978,,,,,245.396385895505,,25,,,9449.0319921875,
,23315132.86,4370,52.5951995849609,0.108000002801418,-7.98000001907349,-461687.5625,0.0992400008440018,,0.0020000000949949,21122.32515625,4.51796001434326,,,28182.6624125018,,715.366948309897,,25,-461687.5625,,21122.32515625,
,23315313.41,4370,46.5608997344971,0.108000002801418,-7.98000001907349,-122488.6575,0.211520000696182,,0.0020000000949949,55256.3846875,1.72599999904633,,,30405.1046277696,,2350.14560145711,,25,-122488.6575,,55256.3846875,
,23315494.28,4370,40.6660003662109,0.108000002801418,-7.98000001907349,-26.689305267334,500,,0.0020000000949949,171789.76,0.549680001735687,,,1.54361094108279,,5824.39770529323,,25,-26.689305267334,,171789.76,
,23315672.64,4370,34.7697505950928,0.108000002801418,-7.98000001907349,-29.7800061035156,500,,0.0020000000949949,691265.3025,0.130959998965263,,,2.297118375225,,19773.608029476,,25,-29.7800061035156,,691265.3025,
,23315853.06,4370,28.7925500869751,0.108000002801418,-7.98000001907349,-26.1144831848145,500,,0.0020000000949949,3879189.57,0.0197999995574355,,,1.85694677775095,,102342.269278725,,25,-26.1144831848145,,3879189.57,
,23316032.59,4370,22.9362001419067,0.108000002801418,-7.98000001907349,,0.0020000000949949,,0.0020000000949949,,0.0020000000949949,,,,,,,25,,,,
,23316213.34,4370,16.9308500289917,0.108000002801418,-7.98000001907349,,0.0020000000949949,,0.00220000009983778,,0.0020000000949949,,,,,,,25,,,,
,23316437.48,4370,9.8132495880127,0.108000002801418,-7.98000001907349,-0.0197731394344009,500,0.0137321736477315,500,-0.00340958300745115,500,,,0.0177310015348235,0.0316401365403651,0.0269396885865144,,25,-0.0197731394344009,0.0137321736477315,-0.00340958300745115,
,23317245.47,4370,3.81264996528625,0.108000002801418,-7.98000001907349,-0.0293694102857262,500,0.00474167784443125,500,-0.0117584453476593,500,,,0.0243620618771508,0.0200202241257099,0.0274432164330567,,25,-0.0293694102857262,0.00474167784443125,-0.0117584453476593,
,23322823.16,4370,5.21080017089844,49999.203125,-7.98000001907349,-0.0395714561268687,500,-0.010429402210284,500,-0.00362473219633102,500,,,0.021777140076522,0.0202150593337357,0.0173061028864678,,25,-0.0395714561268687,-0.010429402210284,-0.00362473219633102,
,23323009.22,4370,11.2383999824524,49999.203125,-7.98000001907349,-0.0334000268764794,500,-0.00192947755334899,500,-0.00581284674466588,500,,,0.0228022890675244,0.0174605034538473,0.0265924195918653,,25,-0.0334000268764794,-0.00192947755334899,-0.00581284674466588,
,23323219.45,4370,18.2074995040894,49999.203125,-7.98000001907349,,0.0020000000949949,0.156846003830433,500,,0.0020000000949949,,,,0.0212499063710958,,,25,,0.156846003830433,,
,23323400.17,4370,24.0999002456665,49999.203125,-7.98000001907349,,0.0020000000949949,,0.0020000000949949,,0.0020000000949949,,,,,,,25,,,,
,23323581.83,4370,30.231499671936,49999.203125,-7.98000001907349,-24.9947068023682,500,,0.0020000000949949,2933168.68,0.0246000003069639,,,1.88651873346432,,88076.98230027,,25,-24.9947068023682,,2933168.68,
,23323762.36,4370,36.2318992614746,49999.203125,-7.98000001907349,-27.1071128082275,500,,0.0020000000949949,533164.01625,0.161640003919601,,,2.48908572890238,,13800.5617461426,,25,-27.1071128082275,,533164.01625,
,23323943.16,4370,42.2208003997803,49999.203125,-7.98000001907349,-22.7053578948975,500,,0.0020000000949949,138082.408125,0.644640023708344,,,1.57384190625132,,2710.92466570241,,25,-22.7053578948975,,138082.408125,
,23324123.55,4370,48.478099822998,49999.203125,-7.98000001907349,-32275.5118401718,317.24551908046,,0.0020000000949949,45460.010625,1.97975997447968,,,73225.3333778715,,2005.80532757895,,25,-32275.5118401718,,45460.010625,
,23324303.45,4370,54.2245998382568,49999.203125,-7.98000001907349,-546226.025,0.0807600006461144,,0.0020000000949949,18865.363671875,4.79639993667603,,,52124.4734143288,,300.21022865779,,25,-546226.025,,18865.363671875,
,23324484.28,4370,60.2033004760742,49999.203125,-7.98000001907349,,0.0020000000949949,,0.0020000000949949,8829.09875,10.2589998245239,,,,,99.5737980654163,,25,,,8829.09875,
,23324664.45,4370,66.2007026672363,49999.203125,-7.98000001907349,,0.0020000000949949,,0.0020000000949949,4586.02826171875,19.6287998199463,,,,,46.0811091951076,,25,,,4586.02826171875,
,23324845.56,4370,72.2198486328125,49999.203125,-7.98000001907349,,0.00212000008672476,3272977.24,0.0195199997723103,2589.63854492188,34.5139999389648,,,,30462.2313925953,22.5657497073484,,25,,3272977.24,2589.63854492188,
,23325026.06,4370,78.2274017333984,49999.203125,-7.98000001907349,,0.0020000000949949,1721097.06,0.0439999997615814,1568.1414453125,57.7331192016602,,,,19304.8206851942,12.0199507605085,,25,,1721097.06,1568.1414453125,
,23325205.50,4370,84.2007026672363,49999.203125,-7.98000001907349,6056739,0.00499999988824129,865050.8925,0.0949999988079071,1008.5375,89.6429977416992,,,40638.9262350651,9670.71850816853,6.8383923684001,,25,6056739,865050.8925,1008.5375,
,23325386.16,4370,90.212100982666,49999.203125,-7.98000001907349,5205084.6,0.0120000001043081,437531.32375,0.195399993062019,674.765822753906,131.919805908203,,,41287.7014715604,4650.26340463451,4.04986143542419,,25,5205084.6,437531.32375,674.765822753906,
,23325565.06,4370,96.1879997253418,49999.203125,-7.98000001907349,2900668.97,0.0276400002092123,229853.536875,0.384200006723404,470.184741210937,193.697998046875,,,31003.1689390879,2391.18713977466,2.66142834394383,,25,2900668.97,229853.536875,470.184741210937,
,23325745.45,4370,102.193248748779,49999.203125,-7.98000001907349,1597674.835,0.0526800003647804,126338.6375,0.699000000953674,340.104376220703,265.031516113281,,,15240.1878997834,1217.81900983622,1.7978471007339,,25,1597674.835,126338.6375,340.104376220703,
,23325925.97,4370,108.218353271484,49999.203125,-7.98000001907349,918969.555,0.0942000010609627,72004.54125,1.25499999523163,252.845814819336,359.990329589844,,,8103.55919525374,639.142552709802,1.2159400138801,,25,918969.555,72004.54125,252.845814819336,
,23326105.97,4370,114.211750030518,49999.203125,-7.98000001907349,551754.5975,0.15888000369072,42836.8046875,2.09431999206543,193.321774291992,462.384002685547,,,4410.95477182486,356.755812383083,0.809752456144105,,25,551754.5975,42836.8046875,193.321774291992,
,23326285.67,4370,120.211799621582,49999.203125,-7.98000001907349,342889.725,0.256000012159348,26355.46328125,3.39776009559631,151.10412902832,500,,,2561.03860319418,202.984433943539,0.583837938802221,,25,342889.725,26355.46328125,151.10412902832,
,23326465.72,4370,126.205249786377,49999.203125,-7.98000001907349,219557.825,0.406000006198883,16759.55609375,5.4229998588562,120.467412109375,500,,,1557.39956278988,120.300907755387,0.430857166977293,,25,219557.825,16759.55609375,120.467412109375,
,23326645.81,4370,132.198348999023,49999.203125,-7.98000001907349,144308.186875,0.617999970912933,10962.80140625,8.30500030517578,97.6090008544922,500,,,936.436867556944,72.1034392478322,0.317551316654527,,25,144308.186875,10962.80140625,97.6090008544922,
,23326826.52,4370,138.22875213623,49999.203125,-7.98000001907349,97009.070625,0.913999974727631,7348.34369140625,12.1639995574951,80.1841320800781,500,,,596.339496492032,45.4596765492125,0.241934500260085,,25,97009.070625,7348.34369140625,80.1841320800781,
,23327005.80,4370,144.206047058105,49999.203125,-7.98000001907349,66694.61625,1.35300004482269,5067.10466796875,17.9039993286133,66.8439370727539,500,,,387.810640589754,29.405130915689,0.191015520018205,,25,66694.61625,5067.10466796875,66.8439370727539,
,23327185.34,4370,150.20059967041,49999.203125,-7.98000001907349,46627.81859375,1.90499997138977,3567.93759765625,25.1100006103516,56.3581869506836,500,,,262.272993254373,19.5873953568571,0.14839408277969,,25,46627.81859375,3567.93759765625,56.3581869506836,
,23327365.86,4370,156.213394165039,49999.203125,-7.98000001907349,33031.660078125,2.69271992683411,2558.28109375,35.2220001220703,47.987144317627,500,,,179.173280728558,13.2432745439182,0.120012346299346,,25,33031.660078125,2558.28109375,47.987144317627,
,23327545.00,4370,162.190353393555,49999.203125,-7.98000001907349,23800.5146875,3.77900004386902,1871.3855078125,47.8476011657715,41.307820892334,500,,,125.503580758981,9.29779571486481,0.0982893238981001,,25,23800.5146875,1871.3855078125,41.307820892334,
,23327725.30,4370,168.198951721191,49999.203125,-7.98000001907349,17285.631640625,5.27072019577026,1391.02519042969,65.4619979858398,35.8401403808594,500,,,86.3581540901592,6.49665759907094,0.0795288508270375,,25,17285.631640625,1391.02519042969,35.8401403808594,
,23327905.09,4370,174.193649291992,49999.203125,-7.98000001907349,12711.327265625,7.03499984741211,1050.81096679687,87.2009963989258,31.3582401275635,500,,,61.4741522990014,4.60551808183095,0.0639410930320935,,25,12711.327265625,1050.81096679687,31.3582401275635,
,23328084.92,4370,180.196502685547,49999.203125,-7.98000001907349,9416.4448828125,9.54059982299805,805.009477539062,110.404998779297,27.6665127563477,500,,,45.8718029735007,3.38545162346602,0.054350488491014,,25,9416.4448828125,805.009477539062,27.6665127563477,
,23328265.92,4370,186.234298706055,49999.203125,-7.98000001907349,7011.0634765625,12.9459196090698,623.562316894531,147.044006347656,24.5516410827637,500,,,33.4443782071304,2.56069326690398,0.0469840318190053,,25,7011.0634765625,623.562316894531,24.5516410827637,
,23328445.13,4370,192.211097717285,49999.203125,-7.98000001907349,5274.93697265625,17.0814005279541,489.873935546875,187.102996826172,21.9175142669678,500,,,24.1907823942772,1.90582582219246,0.0401309428454068,,25,5274.93697265625,489.873935546875,21.9175142669678,
,23328624.50,4370,198.182899475098,49999.203125,-7.98000001907349,3997.70307617188,22.2770004272461,389.078768310547,228.959761352539,19.7028730773926,500,,,17.6441931376514,1.42176595364446,0.0337293748952937,,25,3997.70307617188,389.078768310547,19.7028730773926,
,23328805.06,4370,204.209800720215,49999.203125,-7.98000001907349,3046.96887695312,29.7749996185303,311.832023925781,289.204010009766,17.7811538696289,500,,,13.2454101872102,1.0870343380586,0.0288303625769743,,25,3046.96887695312,311.832023925781,17.7811538696289,
,23328984.19,4370,210.173454284668,49999.203125,-7.98000001907349,2348.82365234375,37.9819984436035,252.822410888672,351.001007080078,16.1623245239258,500,,,9.70111578978318,0.842592790813168,0.024692012791823,,25,2348.82365234375,252.822410888672,16.1623245239258,
,23329165.28,4370,216.221946716309,49999.203125,-7.98000001907349,1819.41274902344,49.5611192321777,206.196813354492,441.045720214844,14.7422025680542,500,,,7.54515899802293,0.697241131474793,0.022056735434255,,25,1819.41274902344,206.196813354492,14.7422025680542,
,23329344.86,4370,222.204849243164,49999.203125,-7.98000001907349,1424.72956542969,63.9959983825684,169.832484741211,500,13.4690877914429,500,,,5.49344381340606,0.519702040418735,0.0185271377646796,,25,1424.72956542969,169.832484741211,13.4690877914429,
,23329525.05,4370,228.210952758789,49999.203125,-7.98000001907349,1123.5745703125,81.0940017700195,141.029822998047,500,12.3493097305298,500,,,4.19521795667221,0.411322601807191,0.016584450021822,,25,1123.5745703125,141.029822998047,12.3493097305298,
,23329704.34,4370,234.202247619629,49999.203125,-7.98000001907349,896.788151855469,100.732722167969,118.076809082031,500,11.4059164047241,500,,,3.20044717526594,0.341043241699773,0.0143246924949126,,25,896.788151855469,118.076809082031,11.4059164047241,
,23329884.39,4370,240.196350097656,49999.203125,-7.98000001907349,702.935642089844,128.725198364258,98.4416143798828,500,10.5278177261353,500,,,2.62778693574802,0.283556054483856,0.0133570610204861,,25,702.935642089844,98.4416143798828,10.5278177261353,
,23330064.94,4370,246.222152709961,49999.203125,-7.98000001907349,561.131901855469,159.013000488281,82.8878897094727,500,9.78041305541992,500,,,1.99982851156921,0.224212275699288,0.0115361878601752,,25,561.131901855469,82.8878897094727,9.78041305541992,
,23330245.14,4370,252.226600646973,49999.203125,-7.98000001907349,449.653707275391,202.246994018555,70.2463821411133,500,9.1160587310791,500,,,1.61797056517123,0.184058557106726,0.00970086938063606,,25,449.653707275391,70.2463821411133,9.1160587310791,
,23330424.42,4370,258.208206176758,49999.203125,-7.98000001907349,362.620576171875,245.236999511719,59.9253549194336,500,8.5241304397583,500,,,1.24602972487381,0.152225087522215,0.0100542581696842,,25,362.620576171875,59.9253549194336,8.5241304397583,
,23330604.14,4370,264.205291748047,49999.203125,-7.98000001907349,292.564318847656,312.164001464844,51.3138105773926,500,7.9759651184082,500,,,1.02525544985657,0.126909428306896,0.00771373502461945,,25,292.564318847656,51.3138105773926,7.9759651184082,
,23330784.45,4370,270.195556640625,49999.203125,-7.98000001907349,236.775618896484,378.846984863281,44.1494827270508,500,7.44940822601318,500,,,0.807948997009135,0.104989211139832,0.013563101229686,,25,236.775618896484,44.1494827270508,7.44940822601318,
,23330964.33,4370,276.201553344727,49999.203125,-7.98000001907349,192.237904052734,462.667047119141,38.1785075378418,500,6.96751823425293,500,,,0.639958286785648,0.088638791031698,0.0078187664051001,,25,192.237904052734,38.1785075378418,6.96751823425293,
,23331145.53,4370,282.231887817383,49999.203125,-7.98000001907349,156.613067016602,500,33.1154539489746,500,6.54952411651611,500,,,0.517634075600665,0.0745362108355712,0.00493772339355792,,25,156.613067016602,33.1154539489746,6.54952411651611,
,23331324.50,4370,288.19255065918,49999.203125,-7.98000001907349,128.401390991211,500,28.8754159545898,500,6.18172334671021,500,,,0.405948575068574,0.0625945801842413,0.00259329350516387,,25,128.401390991211,28.8754159545898,6.18172334671021,
,23331505.27,4370,294.211151123047,49999.203125,-7.98000001907349,105.481624450684,500,25.2376477050781,500,5.82381834030151,500,,,0.32812922162204,0.0529751358473544,0.00478475915535338,,25,105.481624450684,25.2376477050781,5.82381834030151,
,23331684.89,4370,300.210861206055,49999.203125,-7.98000001907349,87.1589767456055,500,22.1427100372314,500,5.54317943572998,500,,,0.266262561180135,0.0467262257871963,0.00484824931083107,,25,87.1589767456055,22.1427100372314,5.54317943572998,
,23331865.45,4370,306.212005615234,49999.203125,-7.98000001907349,72.3899203491211,500,19.4869892883301,500,5.31522760391235,500,,,0.205777193906576,0.0384266951228779,0.00668608727019849,,25,72.3899203491211,19.4869892883301,5.31522760391235,
,23332044.69,4370,312.192245483398,49999.203125,-7.98000001907349,60.1960795593262,500,17.210510635376,500,5.06974342346191,500,,,0.172411138162286,0.0339139921020548,0.0041608737942529,,25,60.1960795593262,17.210510635376,5.06974342346191,
,23332224.73,4370,318.195495605469,49999.203125,-7.98000001907349,50.6641458129883,500,15.2455681228638,500,4.82084341049194,500,,,0.138709093130772,0.0300667792214868,0.00444099918995907,,25,50.6641458129883,15.2455681228638,4.82084341049194,
,23332405.47,4370,324.206893920898,49999.203125,-7.98000001907349,42.4869413757324,500,13.4932027816772,500,4.62883256912231,500,,,0.119129595784743,0.0259557137059509,0.00205028045661949,,25,42.4869413757324,13.4932027816772,4.62883256912231,
,23332584.77,4370,330.178802490234,49999.203125,-7.98000001907349,35.8581280517578,500,11.9807746887207,500,4.44809818267822,500,,,0.0959048964870836,0.02228268288362,0.001084557545429,,25,35.8581280517578,11.9807746887207,4.44809818267822,
,23332765.42,4370,336.19499206543,49999.203125,-7.98000001907349,30.2783257293701,500,10.6572290420532,500,4.24027696609497,500,,,0.0809310362330247,0.0197626824520234,0.00316807380729234,,25,30.2783257293701,10.6572290420532,4.24027696609497,
,23332945.16,4370,342.185195922852,49999.203125,-7.98000001907349,25.6155504608154,500,9.49525737762451,500,4.16128740310669,500,,,0.0678564094264168,0.0174102774844892,0.00345248775103164,,25,25.6155504608154,9.49525737762451,4.16128740310669,
,23333125.30,4370,348.195602416992,49999.203125,-7.98000001907349,21.7784622955322,500,8.47424564361572,500,4.04481750488281,500,,,0.0561960927686366,0.0156348081443631,0.00337946162380907,,25,21.7784622955322,8.47424564361572,4.04481750488281,
,23333305.30,4370,354.190948486328,49999.203125,-7.98000001907349,18.5928821563721,500,7.57364879608154,500,3.93259834289551,500,,,0.04460788142613,0.0138673519438858,0.00313528329884374,,25,18.5928821563721,7.57364879608154,3.93259834289551,
,23333485.80,4370,360.203247070313,49999.203125,-7.98000001907349,15.9349273681641,500,6.76665899276733,500,3.7671990776062,500,,,0.0390412992519923,0.0123241192940373,0.00323821798575869,,25,15.9349273681641,6.76665899276733,3.7671990776062,
,23333665.92,4370,366.221603393555,49999.203125,-7.98000001907349,13.7169174194336,500,6.04911026000977,500,3.60889622688293,500,,,0.0320221485155128,0.0108329037884953,0.00278437713470491,,25,13.7169174194336,6.04911026000977,3.60889622688293,
,23333846.11,4370,372.219650268555,49999.203125,-7.98000001907349,11.8945701599121,500,5.41093608856201,500,3.46804546356201,500,,,0.0268362614261283,0.00973249721651444,0.00173036621696319,,25,11.8945701599121,5.41093608856201,3.46804546356201,
,23334026.33,4370,378.204742431641,49999.203125,-7.98000001907349,10.3886041641235,500,4.84528921127319,500,3.33680865287781,500,,,0.0222436989618474,0.00870606468948965,0.00238342742295378,,25,10.3886041641235,4.84528921127319,3.33680865287781,
,23334206.55,4370,384.221450805664,49999.203125,-7.98000001907349,9.11986122131348,500,4.34003374099731,500,3.19218118667603,500,,,0.0186050643427357,0.00731333772498817,0.00151907514804797,,25,9.11986122131348,4.34003374099731,3.19218118667603,
,23334386.66,4370,390.231597900391,49999.203125,-7.98000001907349,8.05895843505859,500,3.89807776451111,500,3.07466126441956,500,,,0.0158017391651636,0.00668452154884081,0.00196043021674308,,25,8.05895843505859,3.89807776451111,3.07466126441956,
,23334566.33,4370,396.192153930664,49999.203125,-7.98000001907349,7.16777231216431,500,3.51748516082764,500,2.96973793029785,500,,,0.0129275616545369,0.00584383117930855,0.00288552539202798,,25,7.16777231216431,3.51748516082764,2.96973793029785,
,23335893.89,4370,398.854446411133,0.00899999961256981,-7.98000001907349,6.39353260040283,500,3.12587372779846,500,2.91909483909607,500,,,0.00633578699097796,0.00221587778573703,0.00128500534714222,,25,6.39353260040283,3.12587372779846,2.91909483909607,
,23336093.39,4370,391.812454223633,0.00899999961256981,-7.98000001907349,7.10832273483276,500,3.4041606426239,500,3.02825813293457,500,,,0.0123851728669905,0.00478834209173758,0.00160070661041546,,25,7.10832273483276,3.4041606426239,3.02825813293457,
,23336274.06,4370,385.761993408203,0.00899999961256981,-7.98000001907349,7.82124357223511,500,3.67722218513489,500,3.13297944068909,500,,,0.0132063021941081,0.00510644351734322,0.00173304446746292,,25,7.82124357223511,3.67722218513489,3.13297944068909,
,23336455.39,4370,379.788299560547,0.00899999961256981,-7.98000001907349,8.71594409942627,500,4.01069580078125,500,3.24762125015259,500,,,0.0138765556547763,0.00515506481474149,0.0016485453336209,,25,8.71594409942627,4.01069580078125,3.24762125015259,
,23336634.97,4370,373.77766418457,0.00899999961256981,-7.98000001907349,9.68723964691162,500,4.36171648025513,500,3.35228579521179,500,,,0.0172856641279921,0.00614318229134914,0.00182327107657465,,25,9.68723964691162,4.36171648025513,3.35228579521179,
,23336814.88,4370,367.779495239258,0.00899999961256981,-7.98000001907349,10.8466899871826,500,4.76395681381226,500,3.46637889862061,500,,,0.0201104701500496,0.00670163572514608,0.00189124479760111,,25,10.8466899871826,4.76395681381226,3.46637889862061,
,23336993.73,4370,361.793701171875,0.00899999961256981,-7.98000001907349,12.2225900650024,500,5.21962366104126,500,3.59163960456848,500,,,0.0251988551609086,0.00802613320023227,0.00253886361436142,,25,12.2225900650024,5.21962366104126,3.59163960456848,
,23337173.53,4370,355.801742553711,0.00899999961256981,-7.98000001907349,13.9056770324707,500,5.74003477096558,500,3.73472990036011,500,,,0.0292618219364058,0.00874997986230049,0.00218958563627212,,25,13.9056770324707,5.74003477096558,3.73472990036011,
,23337354.39,4370,349.790161132813,0.00899999961256981,-7.98000001907349,15.9050285339355,500,6.33046998977661,500,3.88154273033142,500,,,0.0354919939874915,0.0102642477198584,0.00265160174960705,,25,15.9050285339355,6.33046998977661,3.88154273033142,
,23337533.72,4370,343.81575012207,0.00899999961256981,-7.98000001907349,18.2819679260254,500,6.99350578308106,500,4.04093841552734,500,,,0.0415919064062234,0.0113035139143163,0.00260853568617458,,25,18.2819679260254,6.99350578308106,4.04093841552734,
,23337713.92,4370,337.800399780273,0.00899999961256981,-7.98000001907349,21.1341917419434,500,7.75397138595581,500,4.21311815261841,500,,,0.0506804235120478,0.0128527447317001,0.00291852595535919,,25,21.1341917419434,7.75397138595581,4.21311815261841,
,23337894.75,4370,331.780044555664,0.00899999961256981,-7.98000001907349,24.5399792480469,500,8.62050037384033,500,4.40114261627197,500,,,0.0601710232940541,0.0147216881486713,0.0032058654673896,,25,24.5399792480469,8.62050037384033,4.40114261627197,
,23338073.95,4370,325.812911987305,0.00899999961256981,-7.98000001907349,28.6474000549316,500,9.59638347625732,500,4.60474033355713,500,,,0.0712836727803611,0.0167853475952594,0.00342930276940836,,25,28.6474000549316,9.59638347625732,4.60474033355713,
,23338254.72,4370,319.789199829102,0.00899999961256981,-7.98000001907349,33.6419952392578,500,10.7194918060303,500,4.82139791488647,500,,,0.0874158291242307,0.0188835899315582,0.00363694632588119,,25,33.6419952392578,10.7194918060303,4.82139791488647,
,23338434.14,4370,313.812652587891,0.00899999961256981,-7.98000001907349,39.6088619995117,500,12.0031646728516,500,5.05531135559082,500,,,0.106782273604656,0.0221280410049368,0.00394646278428659,,25,39.6088619995117,12.0031646728516,5.05531135559082,
,23338615.13,4370,307.775207519531,0.00899999961256981,-7.98000001907349,47.0238377380371,500,13.4926610946655,500,5.30498071670532,500,,,0.131772004218928,0.0258703418500314,0.00400355809743453,,25,47.0238377380371,13.4926610946655,5.30498071670532,
,23338794.16,4370,301.81379699707,0.00899999961256981,-7.98000001907349,55.9729911804199,500,15.2073239135742,500,5.56965129852295,500,,,0.163707118748216,0.0306012048082579,0.0045095122507138,,25,55.9729911804199,15.2073239135742,5.56965129852295,
,23338974.31,4370,295.810897827148,0.00899999961256981,-7.98000001907349,67.1812963867188,500,17.2074794769287,500,5.86037595748901,500,,,0.205075660769968,0.0352236123905008,0.0049372717745327,,25,67.1812963867188,17.2074794769287,5.86037595748901,
,23339155.25,4370,289.786346435547,0.00899999961256981,-7.98000001907349,81.1760198974609,500,19.5356994628906,500,6.17688447952271,500,,,0.24739635835587,0.0403581142505538,0.00533575853434975,,25,81.1760198974609,19.5356994628906,6.17688447952271,
,23339335.06,4370,283.798553466797,0.00899999961256981,-7.98000001907349,98.4830395507813,500,22.2203298187256,500,6.51956287384033,500,,,0.329075955709871,0.0466498576737051,0.0058510320073723,,25,98.4830395507813,22.2203298187256,6.51956287384033,
,23339515.25,4370,277.793960571289,0.00899999961256981,-7.98000001907349,120.590913391113,500,25.4871405029297,500,6.90370079040527,500,,,0.381689344261203,0.0568856331293751,0.00638369720622027,,25,120.590913391113,25.4871405029297,6.90370079040527,
,23339695.58,4370,271.78044128418,0.00899999961256981,-7.98000001907349,148.465411987305,500,29.34464012146,500,7.32586557388306,500,,,0.507495231811947,0.0681277239363929,0.00723183751204269,,25,148.465411987305,29.34464012146,7.32586557388306,
,23339874.78,4370,265.803009033203,0.00899999961256981,-7.98000001907349,184.193980102539,500,33.6362208557129,500,7.80795621871948,500,,,0.644014557986295,0.0768727487539946,0.00826086763355931,,25,184.193980102539,33.6362208557129,7.80795621871948,
,23340055.38,4370,259.673446655273,0.00899999961256981,-7.98000001907349,230.949852294922,411.646361083984,39.0747071838379,500,8.39108295440674,500,,,1.53590548656496,0.179984451032834,0.0183689664329096,,25,230.949852294922,39.0747071838379,8.39108295440674,
,23340235.20,4370,253.732704162598,0.00899999961256981,-7.98000001907349,286.378304443359,331.900360107422,45.5638442993164,500,9.01872520446777,500,,,1.59229151073493,0.160637354230165,0.0147058330871724,,25,286.378304443359,45.5638442993164,9.01872520446777,
,23340415.23,4370,247.750495910645,0.00899999961256981,-7.98000001907349,354.269311523438,268.285283203125,53.310560760498,500,9.67194957733154,500,,,1.67291605751865,0.185053413344338,0.0148488787997462,,25,354.269311523438,53.310560760498,9.67194957733154,
,23340595.55,4370,241.773300170898,0.00899999961256981,-7.98000001907349,438.081033935547,216.795319213867,62.6266912841797,500,10.3814012527466,500,,,1.75388133744616,0.190681528191076,0.0136177456883783,,25,438.081033935547,62.6266912841797,10.3814012527466,
,23340775.69,4370,235.765899658203,0.00899999961256981,-7.98000001907349,542.979841308594,174.938958740234,73.8175378417969,500,11.1550601959229,500,,,2.11997428524292,0.223089652771099,0.0147947275583787,,25,542.979841308594,73.8175378417969,11.1550601959229,
,23340955.61,4370,229.763793945313,0.00899999961256981,-7.98000001907349,674.182331542969,140.859682006836,87.3987518310547,500,12.0160461425781,500,,,2.62849329747781,0.268774605431227,0.0162731862033314,,25,674.182331542969,87.3987518310547,12.0160461425781,
,23341135.31,4370,223.78630065918,0.00899999961256981,-7.98000001907349,840.567485351562,112.985,104.084559020996,500,12.980447769165,500,,,3.29508550900562,0.325116069489126,0.0177144527563016,,25,840.567485351562,104.084559020996,12.980447769165,
,23341315.02,4370,217.78604888916,0.00899999961256981,-7.98000001907349,1053.78336914062,90.0829608154297,124.692978515625,500,14.0752784729004,500,,,4.15890382324113,0.397785793659085,0.0201613561106156,,25,1053.78336914062,124.692978515625,14.0752784729004,
,23341495.28,4370,211.775894165039,0.00899999961256981,-7.98000001907349,1330.62915039063,71.2945593261719,150.630103759766,500,15.3363508224487,500,,,5.27629741717092,0.493841406671113,0.0229913041076332,,25,1330.62915039063,150.630103759766,15.3363508224487,
,23341675.31,4370,205.775848388672,0.00899999961256981,-7.98000001907349,1690.95122558594,56.0724406433106,183.253635864258,500,16.7802822113037,500,,,6.86525318755669,0.622767925311922,0.0261956718782183,,25,1690.95122558594,183.253635864258,16.7802822113037,
,23341855.27,4370,199.555503845215,0.00899999961256981,-7.98000001907349,2181.67861328125,43.5994401550293,226.448193359375,419.462679443359,18.4884552764893,500,,,21.9186027928811,1.85708392015755,0.0702554031561406,,25,2181.67861328125,226.448193359375,18.4884552764893,
,23342035.23,4370,193.630798339844,0.00899999961256981,-7.98000001907349,2806.52575195313,33.8788803100586,279.944211425781,339.335638427734,20.4077849578857,500,,,24.3288024436575,1.97293061654242,0.0664597392888244,,25,2806.52575195313,279.944211425781,20.4077849578857,
,23342214.78,4370,187.679496765137,0.00899999961256981,-7.98000001907349,3643.847109375,26.0928000640869,349.474722900391,271.8515625,22.6456611633301,500,,,28.4834146704271,2.28178161760208,0.0680559790506422,,25,3643.847109375,349.474722900391,22.6456611633301,
,23342395.14,4370,181.687149047852,0.00899999961256981,-7.98000001907349,4776.9513671875,19.8925198364258,441.312266845703,215.349240722656,25.2893955993652,500,,,35.3837722472119,2.78519336396309,0.0743685346722578,,25,4776.9513671875,441.312266845703,25.2893955993652,
,23342574.80,4370,175.73860168457,0.00899999961256981,-7.98000001907349,6320.41580078125,15.0268799972534,562.686640625,168.871559448242,28.4167628479004,500,,,40.4989265847677,3.19650896546191,0.0748074139005874,,25,6320.41580078125,562.686640625,28.4167628479004,
,23342755.19,4370,169.737800598145,0.00899999961256981,-7.98000001907349,8469.756875,11.2134800338745,727.913732910156,130.434838867187,32.1787133789063,500,,,50.8535270784672,3.83670160178548,0.0830923361501978,,25,8469.756875,727.913732910156,32.1787133789063,
,23342935.23,4370,163.745948791504,0.00899999961256981,-7.98000001907349,11457.5652734375,8.28136005401611,952.933522949219,99.6386001586914,36.7154672241211,500,,,67.8010064597306,5.04538942246666,0.0952033632414945,,25,11457.5652734375,952.933522949219,36.7154672241211,
,23343115.22,4370,157.749046325684,0.00899999961256981,-7.98000001907349,15716.0469921875,6.03803998947144,1266.86162109375,74.8510403442383,42.2674731445313,500,,,94.9893530971731,6.92171822914559,0.114789210663882,,25,15716.0469921875,1266.86162109375,42.2674731445313,
,23343294.00,4370,151.588897705078,0.00899999961256981,-7.98000001907349,22033.61859375,4.31840000152588,1722.70999511719,55.0268403625488,49.2805743408203,500,,,294.1347726532,20.9055331120883,0.297183364777898,,25,22033.61859375,1722.70999511719,49.2805743408203,
,23343474.89,4370,145.533699035645,0.00899999961256981,-7.98000001907349,31174.125234375,3.05103999137878,2376.45350585938,40.0439602661133,57.951981048584,500,,,459.809181183383,33.4440876701502,0.406974339817674,,25,31174.125234375,2376.45350585938,57.951981048584,
,23343654.13,4370,139.613349914551,0.00899999961256981,-7.98000001907349,44435.570625,2.13883999824524,3302.8287890625,28.7962800598145,68.6623132324219,500,,,585.693416132859,40.8706899539324,0.428400778584577,,25,44435.570625,3302.8287890625,68.6623132324219,
,23343834.53,4370,133.660095214844,0.00899999961256981,-7.98000001907349,64691.4053125,1.46815999984741,4681.9135546875,20.2823199462891,82.4500296020508,500,,,750.276902770859,52.151183197661,0.471792305582596,,25,64691.4053125,4681.9135546875,82.4500296020508,
,23344014.75,4370,127.685249328613,0.00899999961256981,-7.98000001907349,95955.8615625,0.986720006465912,6780.89384765625,14.0087999343872,100.492714538574,500,,,1001.48848916198,68.6073827980433,0.531838603616958,,25,95955.8615625,6780.89384765625,100.492714538574,
,23344194.03,4370,121.767196655273,0.00899999961256981,-7.98000001907349,145786.71375,0.648639996051788,10001.248671875,9.48700000762939,124.318539428711,500,,,1275.5611149477,81.7027134573087,0.55742357331288,,25,145786.71375,10001.248671875,124.318539428711,
,23344374.09,4370,115.776550292969,0.00899999961256981,-7.98000001907349,228205.48875,0.412999997138977,15147.229453125,6.25591999053955,156.776835327148,500,,,1983.27394757947,120.946974415866,0.706589376323491,,25,228205.48875,15147.229453125,156.776835327148,
,23344554.28,4370,109.531551361084,0.00899999961256981,-7.98000001907349,375721.68875,0.24944000184536,23970.838125,3.96580001831055,204.162055053711,465.618039550781,,,8128.36636814676,482.243990893323,2.41408374179213,,25,375721.68875,23970.838125,204.162055053711,
,23344734.00,4370,103.539951324463,0.00899999961256981,-7.98000001907349,630328.9525,0.146959998607636,38156.31265625,2.48412000656128,270.206231689453,352.115281982422,,,14714.9794190242,804.352678840367,3.4747435912521,,25,630328.9525,38156.31265625,270.206231689453,
,23344914.20,4370,97.5978012084961,0.00899999961256981,-7.98000001907349,1099080.37,0.0828399991989136,62230.1590625,1.51988000869751,366.120498046875,259.540680541992,,,23511.8173877572,1146.26990269508,4.46333173506678,,25,1099080.37,62230.1590625,366.120498046875,
,23345094.47,4370,91.6721000671387,0.00899999961256981,-7.98000001907349,1998579.385,0.0439999997615814,103529.9034375,0.908759999275208,511.437449951172,185.862161254883,,,34993.2119976308,1481.49666502967,5.21215530203165,,25,1998579.385,103529.9034375,511.437449951172,
,23345273.91,4370,85.721248626709,0.00899999961256981,-7.98000001907349,3785265.08,0.021799999922514,177632.709375,0.525399997234345,742.187443847656,128.050798950195,,,58707.1446974168,2340.33645223656,7.10922387656455,,25,3785265.08,177632.709375,742.187443847656,
,23345453.88,4370,79.7696495056152,0.00899999961256981,-7.98000001907349,6116140.02,0.00999999977648258,314182.06375,0.293600004911423,1127.25713867188,84.1718801879883,,,64831.7013150082,3550.65911535987,9.61259314369853,,25,6116140.02,314182.06375,1127.25713867188,
,23345634.64,4370,73.7772979736328,0.00899999961256981,-7.98000001907349,2975406.83,0.00499999988824129,570762.8175,0.157919998764992,1811.31302734375,52.3496800231934,,,208830.160899256,6230.84060495437,16.4046290706691,,25,2975406.83,570762.8175,1811.31302734375,
,23345814.11,4370,67.6152000427246,0.00899999961256981,-7.98000001907349,,0.0020000000949949,1085247.0525,0.0793599998950958,3181.10859375,29.9502800750732,,,,25125.993767461,69.1376497951564,,25,,1085247.0525,3181.10859375,
,23345994.81,4370,61.6013507843018,0.00899999961256981,-7.98000001907349,,0.0020000000949949,2067994.48,0.0380400006473064,5970.92693359375,15.9540399551392,,,,47453.9180332977,148.577348109462,,25,,2067994.48,5970.92693359375,
,23346176.45,4370,55.6864490509033,0.00899999961256981,-7.98000001907349,,0.0020000000949949,3712541.22,0.0151200000569224,12281.54515625,7.73903999328613,,,,97066.9743145929,230.081325343984,,25,,3712541.22,12281.54515625,
,23346353.36,4370,49.5587005615234,0.00899999961256981,-7.98000001907349,-607192.3775,0.0640000009536743,,0.0020000000949949,29800.65703125,3.20407999038696,,,73082.1104941017,,1171.84392988393,,25,-607192.3775,,29800.65703125,
,23346535.00,4370,43.5414009094238,0.00899999961256981,-7.98000001907349,-129512.9884375,0.210239999592304,,0.0020000000949949,85529.290625,1.11428000450134,,,39706.9716898521,,4046.85166354947,,25,-129512.9884375,,85529.290625,
,23346714.19,4370,37.7970008850098,0.00899999961256981,-7.98000001907349,-25.0921403503418,500,,0.0020000000949949,290765.27125,0.321799997091293,,,1.96250972610878,,7529.37118127244,,25,-25.0921403503418,,290765.27125,
,23346894.14,4370,31.7932996749878,0.00899999961256981,-7.98000001907349,-25.0799323272705,500,,0.0020000000949949,1448363.29,0.0595200009644032,,,1.7405978646356,,43681.0448509785,,25,-25.0799323272705,,1448363.29,
,23347074.89,4370,25.7491998672485,0.00899999961256981,-7.98000001907349,-25.975159072876,460.214918823242,,0.0020000000949949,,0.0020000000949949,,,8.34438609370514,,,,25,-25.975159072876,,,
,23347253.78,4370,19.9381999969482,0.00899999961256981,-7.98000001907349,,0.0020000000949949,,0.0020000000949949,,0.0020000000949949,,,,,,,25,,,,
,23347435.63,4370,13.2587003707886,0.00899999961256981,-7.98000001907349,-3888.02329009056,29.6082399618626,-420423.30620224,47.0323209389299,-692934.445845468,35.3819994075596,,,10613.0498117714,630408.507861041,785606.061283774,,24,-3888.02329009056,-420423.30620224,-692934.445845468,
,23347839.73,4375,8.11940026283264,0.00899999961256981,-7.98000001907349,-0.0183700913842767,500,0.018400608850643,500,-0.00013809229596518,500,,,0.0286248696117682,0.0227538990869917,0.0240893289580871,,25,-0.0183700913842767,0.018400608850643,-0.00013809229596518,